urllib3.connectionpool:DEBUG:2022-10-03 15:09:40,480:Starting new HTTPS connection (1): free-proxy-list.net:443
urllib3.connectionpool:DEBUG:2022-10-03 15:09:41,154:https://free-proxy-list.net:443 "GET / HTTP/1.1" 200 None
urllib3.connectionpool:DEBUG:2022-10-03 15:09:41,286:Starting new HTTPS connection (1): www.newegg.com:443
urllib3.connectionpool:DEBUG:2022-10-03 15:09:42,300:https://www.newegg.com:443 "GET /p/pl?N=100008225%20600030002 HTTP/1.1" 200 68053
urllib3.connectionpool:DEBUG:2022-10-03 15:12:01,435:Starting new HTTPS connection (1): free-proxy-list.net:443
urllib3.connectionpool:DEBUG:2022-10-03 15:12:01,956:https://free-proxy-list.net:443 "GET / HTTP/1.1" 200 None
urllib3.connectionpool:DEBUG:2022-10-03 15:12:02,096:Starting new HTTPS connection (1): www.newegg.com:443
urllib3.connectionpool:DEBUG:2022-10-03 15:12:03,854:https://www.newegg.com:443 "GET /p/pl?N=100008225%20600030002 HTTP/1.1" 200 None
urllib3.connectionpool:DEBUG:2022-10-03 15:14:44,548:Starting new HTTPS connection (1): free-proxy-list.net:443
urllib3.connectionpool:DEBUG:2022-10-03 15:14:45,117:https://free-proxy-list.net:443 "GET / HTTP/1.1" 200 None
urllib3.connectionpool:DEBUG:2022-10-03 15:14:45,259:Starting new HTTPS connection (1): www.newegg.com:443
urllib3.connectionpool:DEBUG:2022-10-03 15:14:46,623:https://www.newegg.com:443 "GET /p/pl?N=100008225%20600030002 HTTP/1.1" 200 None
urllib3.connectionpool:DEBUG:2022-10-03 15:15:35,863:Starting new HTTPS connection (1): free-proxy-list.net:443
urllib3.connectionpool:DEBUG:2022-10-03 15:15:36,506:https://free-proxy-list.net:443 "GET / HTTP/1.1" 200 None
urllib3.connectionpool:DEBUG:2022-10-03 15:15:36,663:Starting new HTTPS connection (1): www.newegg.com:443
urllib3.connectionpool:DEBUG:2022-10-03 15:15:38,232:https://www.newegg.com:443 "GET /p/pl?N=100008225%20600030002 HTTP/1.1" 200 None
urllib3.connectionpool:DEBUG:2022-10-03 15:37:00,666:Starting new HTTPS connection (1): free-proxy-list.net:443
urllib3.connectionpool:DEBUG:2022-10-03 15:37:01,438:https://free-proxy-list.net:443 "GET / HTTP/1.1" 200 None
urllib3.connectionpool:DEBUG:2022-10-03 15:37:01,585:Starting new HTTPS connection (1): www.newegg.com:443
urllib3.connectionpool:DEBUG:2022-10-03 15:37:01,979:https://www.newegg.com:443 "GET /cerwin-vega-xls-215/p/0S6-00AA-00006?quicklink=true HTTP/1.1" 200 24570
root:INFO:2022-10-03 15:37:02,046:No product id.
urllib3.connectionpool:DEBUG:2022-10-03 15:37:23,673:Starting new HTTPS connection (1): free-proxy-list.net:443
urllib3.connectionpool:DEBUG:2022-10-03 15:37:24,187:https://free-proxy-list.net:443 "GET / HTTP/1.1" 200 None
urllib3.connectionpool:DEBUG:2022-10-03 15:37:24,391:Starting new HTTPS connection (1): www.newegg.com:443
urllib3.connectionpool:DEBUG:2022-10-03 15:37:25,348:https://www.newegg.com:443 "GET /cerwin-vega-xls-215/p/0S6-00AA-00006?quicklink=true HTTP/1.1" 200 24570
urllib3.connectionpool:DEBUG:2022-10-03 15:37:55,203:Starting new HTTPS connection (1): free-proxy-list.net:443
urllib3.connectionpool:DEBUG:2022-10-03 15:37:55,755:https://free-proxy-list.net:443 "GET / HTTP/1.1" 200 None
urllib3.connectionpool:DEBUG:2022-10-03 15:37:56,441:Starting new HTTPS connection (1): www.newegg.com:443
urllib3.connectionpool:DEBUG:2022-10-03 15:37:57,245:https://www.newegg.com:443 "GET /cerwin-vega-xls-215/p/0S6-00AA-00006?quicklink=true HTTP/1.1" 200 25290
urllib3.connectionpool:DEBUG:2022-10-03 15:46:39,291:Starting new HTTPS connection (1): free-proxy-list.net:443
urllib3.connectionpool:DEBUG:2022-10-03 15:46:40,021:https://free-proxy-list.net:443 "GET / HTTP/1.1" 200 None
urllib3.connectionpool:DEBUG:2022-10-03 15:46:40,199:Starting new HTTPS connection (1): www.newegg.com:443
urllib3.connectionpool:DEBUG:2022-10-03 15:46:41,650:https://www.newegg.com:443 "GET /cerwin-vega-xls-215/p/0S6-00AA-00006?quicklink=true HTTP/1.1" 200 25290
urllib3.connectionpool:DEBUG:2022-10-03 16:22:37,274:Starting new HTTPS connection (1): free-proxy-list.net:443
urllib3.connectionpool:DEBUG:2022-10-03 16:22:38,148:https://free-proxy-list.net:443 "GET / HTTP/1.1" 200 None
urllib3.connectionpool:DEBUG:2022-10-03 16:22:38,346:Starting new HTTPS connection (1): www.newegg.com:443
urllib3.connectionpool:DEBUG:2022-10-03 16:22:42,052:https://www.newegg.com:443 "GET /cerwin-vega-xls-215/p/0S6-00AA-00006?quicklink=true HTTP/1.1" 200 25290
urllib3.connectionpool:DEBUG:2022-10-03 16:24:03,211:Starting new HTTPS connection (1): free-proxy-list.net:443
urllib3.connectionpool:DEBUG:2022-10-03 16:24:03,771:https://free-proxy-list.net:443 "GET / HTTP/1.1" 200 None
urllib3.connectionpool:DEBUG:2022-10-03 16:24:03,940:Starting new HTTPS connection (1): www.newegg.com:443
urllib3.connectionpool:DEBUG:2022-10-03 16:24:06,717:https://www.newegg.com:443 "GET /cerwin-vega-xls-215/p/0S6-00AA-00006?quicklink=true HTTP/1.1" 200 24570
urllib3.connectionpool:DEBUG:2022-10-03 16:25:08,269:Starting new HTTPS connection (1): free-proxy-list.net:443
urllib3.connectionpool:DEBUG:2022-10-03 16:25:08,847:https://free-proxy-list.net:443 "GET / HTTP/1.1" 200 None
urllib3.connectionpool:DEBUG:2022-10-03 16:25:08,988:Starting new HTTPS connection (1): www.newegg.com:443
root:ERROR:2022-10-03 16:25:12,530:HTTPSConnectionPool(host='www.newegg.com', port=443): Max retries exceeded with url: /cerwin-vega-xls-215/p/0S6-00AA-00006?quicklink=true (Caused by ProxyError('Cannot connect to proxy.', ConnectionResetError(10054, 'An existing connection was forcibly closed by the remote host', None, 10054, None)))
Traceback (most recent call last):
  File "C:\Users\DELL\anaconda3\envs\Products_scraper\lib\site-packages\urllib3\connectionpool.py", line 700, in urlopen
    self._prepare_proxy(conn)
  File "C:\Users\DELL\anaconda3\envs\Products_scraper\lib\site-packages\urllib3\connectionpool.py", line 996, in _prepare_proxy
    conn.connect()
  File "C:\Users\DELL\anaconda3\envs\Products_scraper\lib\site-packages\urllib3\connection.py", line 369, in connect
    self._tunnel()
  File "C:\Users\DELL\anaconda3\envs\Products_scraper\lib\http\client.py", line 920, in _tunnel
    (version, code, message) = response._read_status()
  File "C:\Users\DELL\anaconda3\envs\Products_scraper\lib\http\client.py", line 279, in _read_status
    line = str(self.fp.readline(_MAXLINE + 1), "iso-8859-1")
  File "C:\Users\DELL\anaconda3\envs\Products_scraper\lib\socket.py", line 705, in readinto
    return self._sock.recv_into(b)
ConnectionResetError: [WinError 10054] An existing connection was forcibly closed by the remote host

During handling of the above exception, another exception occurred:

Traceback (most recent call last):
  File "C:\Users\DELL\anaconda3\envs\Products_scraper\lib\site-packages\requests\adapters.py", line 489, in send
    resp = conn.urlopen(
  File "C:\Users\DELL\anaconda3\envs\Products_scraper\lib\site-packages\urllib3\connectionpool.py", line 787, in urlopen
    retries = retries.increment(
  File "C:\Users\DELL\anaconda3\envs\Products_scraper\lib\site-packages\urllib3\util\retry.py", line 592, in increment
    raise MaxRetryError(_pool, url, error or ResponseError(cause))
urllib3.exceptions.MaxRetryError: HTTPSConnectionPool(host='www.newegg.com', port=443): Max retries exceeded with url: /cerwin-vega-xls-215/p/0S6-00AA-00006?quicklink=true (Caused by ProxyError('Cannot connect to proxy.', ConnectionResetError(10054, 'An existing connection was forcibly closed by the remote host', None, 10054, None)))

During handling of the above exception, another exception occurred:

Traceback (most recent call last):
  File "C:\Users\DELL\Desktop\Python work\Products_scraper\extractors\send_request.py", line 71, in send_request
    page = requests.get(url, headers=HEADERS, proxies=ip)
  File "C:\Users\DELL\anaconda3\envs\Products_scraper\lib\site-packages\requests\api.py", line 73, in get
    return request("get", url, params=params, **kwargs)
  File "C:\Users\DELL\anaconda3\envs\Products_scraper\lib\site-packages\requests\api.py", line 59, in request
    return session.request(method=method, url=url, **kwargs)
  File "C:\Users\DELL\anaconda3\envs\Products_scraper\lib\site-packages\requests\sessions.py", line 587, in request
    resp = self.send(prep, **send_kwargs)
  File "C:\Users\DELL\anaconda3\envs\Products_scraper\lib\site-packages\requests\sessions.py", line 701, in send
    r = adapter.send(request, **kwargs)
  File "C:\Users\DELL\anaconda3\envs\Products_scraper\lib\site-packages\requests\adapters.py", line 559, in send
    raise ProxyError(e, request=request)
requests.exceptions.ProxyError: HTTPSConnectionPool(host='www.newegg.com', port=443): Max retries exceeded with url: /cerwin-vega-xls-215/p/0S6-00AA-00006?quicklink=true (Caused by ProxyError('Cannot connect to proxy.', ConnectionResetError(10054, 'An existing connection was forcibly closed by the remote host', None, 10054, None)))
urllib3.connectionpool:DEBUG:2022-10-03 16:25:12,622:Starting new HTTPS connection (1): www.newegg.com:443
urllib3.connectionpool:DEBUG:2022-10-03 16:25:32,283:https://www.newegg.com:443 "GET /cerwin-vega-xls-215/p/0S6-00AA-00006?quicklink=true HTTP/1.1" 200 25290
urllib3.connectionpool:DEBUG:2022-10-03 16:32:18,058:Starting new HTTPS connection (1): free-proxy-list.net:443
urllib3.connectionpool:DEBUG:2022-10-03 16:32:18,806:https://free-proxy-list.net:443 "GET / HTTP/1.1" 200 None
urllib3.connectionpool:DEBUG:2022-10-03 16:32:18,950:Starting new HTTPS connection (1): www.newegg.com:443
urllib3.connectionpool:DEBUG:2022-10-03 16:32:35,793:https://www.newegg.com:443 "GET /cerwin-vega-xls-215/p/0S6-00AA-00006?quicklink=true HTTP/1.1" 200 25290
urllib3.connectionpool:DEBUG:2022-10-03 16:40:29,119:Starting new HTTPS connection (1): free-proxy-list.net:443
urllib3.connectionpool:DEBUG:2022-10-03 16:40:29,694:https://free-proxy-list.net:443 "GET / HTTP/1.1" 200 None
urllib3.connectionpool:DEBUG:2022-10-03 16:40:29,836:Starting new HTTPS connection (1): www.newegg.com:443
root:ERROR:2022-10-03 16:40:32,382:HTTPSConnectionPool(host='www.newegg.com', port=443): Max retries exceeded with url: /cerwin-vega-xls-215/p/0S6-00AA-00006?quicklink=true (Caused by ProxyError('Cannot connect to proxy.', ConnectionResetError(10054, 'An existing connection was forcibly closed by the remote host', None, 10054, None)))
Traceback (most recent call last):
  File "C:\Users\DELL\anaconda3\envs\Products_scraper\lib\site-packages\urllib3\connectionpool.py", line 700, in urlopen
    self._prepare_proxy(conn)
  File "C:\Users\DELL\anaconda3\envs\Products_scraper\lib\site-packages\urllib3\connectionpool.py", line 996, in _prepare_proxy
    conn.connect()
  File "C:\Users\DELL\anaconda3\envs\Products_scraper\lib\site-packages\urllib3\connection.py", line 369, in connect
    self._tunnel()
  File "C:\Users\DELL\anaconda3\envs\Products_scraper\lib\http\client.py", line 920, in _tunnel
    (version, code, message) = response._read_status()
  File "C:\Users\DELL\anaconda3\envs\Products_scraper\lib\http\client.py", line 279, in _read_status
    line = str(self.fp.readline(_MAXLINE + 1), "iso-8859-1")
  File "C:\Users\DELL\anaconda3\envs\Products_scraper\lib\socket.py", line 705, in readinto
    return self._sock.recv_into(b)
ConnectionResetError: [WinError 10054] An existing connection was forcibly closed by the remote host

During handling of the above exception, another exception occurred:

Traceback (most recent call last):
  File "C:\Users\DELL\anaconda3\envs\Products_scraper\lib\site-packages\requests\adapters.py", line 489, in send
    resp = conn.urlopen(
  File "C:\Users\DELL\anaconda3\envs\Products_scraper\lib\site-packages\urllib3\connectionpool.py", line 787, in urlopen
    retries = retries.increment(
  File "C:\Users\DELL\anaconda3\envs\Products_scraper\lib\site-packages\urllib3\util\retry.py", line 592, in increment
    raise MaxRetryError(_pool, url, error or ResponseError(cause))
urllib3.exceptions.MaxRetryError: HTTPSConnectionPool(host='www.newegg.com', port=443): Max retries exceeded with url: /cerwin-vega-xls-215/p/0S6-00AA-00006?quicklink=true (Caused by ProxyError('Cannot connect to proxy.', ConnectionResetError(10054, 'An existing connection was forcibly closed by the remote host', None, 10054, None)))

During handling of the above exception, another exception occurred:

Traceback (most recent call last):
  File "C:\Users\DELL\Desktop\Python work\Products_scraper\extractors\send_request.py", line 71, in send_request
    page = requests.get(url, headers=HEADERS, proxies=ip)
  File "C:\Users\DELL\anaconda3\envs\Products_scraper\lib\site-packages\requests\api.py", line 73, in get
    return request("get", url, params=params, **kwargs)
  File "C:\Users\DELL\anaconda3\envs\Products_scraper\lib\site-packages\requests\api.py", line 59, in request
    return session.request(method=method, url=url, **kwargs)
  File "C:\Users\DELL\anaconda3\envs\Products_scraper\lib\site-packages\requests\sessions.py", line 587, in request
    resp = self.send(prep, **send_kwargs)
  File "C:\Users\DELL\anaconda3\envs\Products_scraper\lib\site-packages\requests\sessions.py", line 701, in send
    r = adapter.send(request, **kwargs)
  File "C:\Users\DELL\anaconda3\envs\Products_scraper\lib\site-packages\requests\adapters.py", line 559, in send
    raise ProxyError(e, request=request)
requests.exceptions.ProxyError: HTTPSConnectionPool(host='www.newegg.com', port=443): Max retries exceeded with url: /cerwin-vega-xls-215/p/0S6-00AA-00006?quicklink=true (Caused by ProxyError('Cannot connect to proxy.', ConnectionResetError(10054, 'An existing connection was forcibly closed by the remote host', None, 10054, None)))
urllib3.connectionpool:DEBUG:2022-10-03 16:40:32,414:Starting new HTTPS connection (1): www.newegg.com:443
root:ERROR:2022-10-03 16:40:53,453:HTTPSConnectionPool(host='www.newegg.com', port=443): Max retries exceeded with url: /cerwin-vega-xls-215/p/0S6-00AA-00006?quicklink=true (Caused by ConnectTimeoutError(<urllib3.connection.HTTPSConnection object at 0x000001F645B882B0>, 'Connection to 89.107.197.165 timed out. (connect timeout=None)'))
Traceback (most recent call last):
  File "C:\Users\DELL\anaconda3\envs\Products_scraper\lib\site-packages\urllib3\connection.py", line 174, in _new_conn
    conn = connection.create_connection(
  File "C:\Users\DELL\anaconda3\envs\Products_scraper\lib\site-packages\urllib3\util\connection.py", line 95, in create_connection
    raise err
  File "C:\Users\DELL\anaconda3\envs\Products_scraper\lib\site-packages\urllib3\util\connection.py", line 85, in create_connection
    sock.connect(sa)
TimeoutError: [WinError 10060] A connection attempt failed because the connected party did not properly respond after a period of time, or established connection failed because connected host has failed to respond

During handling of the above exception, another exception occurred:

Traceback (most recent call last):
  File "C:\Users\DELL\anaconda3\envs\Products_scraper\lib\site-packages\urllib3\connectionpool.py", line 700, in urlopen
    self._prepare_proxy(conn)
  File "C:\Users\DELL\anaconda3\envs\Products_scraper\lib\site-packages\urllib3\connectionpool.py", line 996, in _prepare_proxy
    conn.connect()
  File "C:\Users\DELL\anaconda3\envs\Products_scraper\lib\site-packages\urllib3\connection.py", line 358, in connect
    self.sock = conn = self._new_conn()
  File "C:\Users\DELL\anaconda3\envs\Products_scraper\lib\site-packages\urllib3\connection.py", line 179, in _new_conn
    raise ConnectTimeoutError(
urllib3.exceptions.ConnectTimeoutError: (<urllib3.connection.HTTPSConnection object at 0x000001F645B882B0>, 'Connection to 89.107.197.165 timed out. (connect timeout=None)')

During handling of the above exception, another exception occurred:

Traceback (most recent call last):
  File "C:\Users\DELL\anaconda3\envs\Products_scraper\lib\site-packages\requests\adapters.py", line 489, in send
    resp = conn.urlopen(
  File "C:\Users\DELL\anaconda3\envs\Products_scraper\lib\site-packages\urllib3\connectionpool.py", line 787, in urlopen
    retries = retries.increment(
  File "C:\Users\DELL\anaconda3\envs\Products_scraper\lib\site-packages\urllib3\util\retry.py", line 592, in increment
    raise MaxRetryError(_pool, url, error or ResponseError(cause))
urllib3.exceptions.MaxRetryError: HTTPSConnectionPool(host='www.newegg.com', port=443): Max retries exceeded with url: /cerwin-vega-xls-215/p/0S6-00AA-00006?quicklink=true (Caused by ConnectTimeoutError(<urllib3.connection.HTTPSConnection object at 0x000001F645B882B0>, 'Connection to 89.107.197.165 timed out. (connect timeout=None)'))

During handling of the above exception, another exception occurred:

Traceback (most recent call last):
  File "C:\Users\DELL\Desktop\Python work\Products_scraper\extractors\send_request.py", line 71, in send_request
    page = requests.get(url, headers=HEADERS, proxies=ip)
  File "C:\Users\DELL\anaconda3\envs\Products_scraper\lib\site-packages\requests\api.py", line 73, in get
    return request("get", url, params=params, **kwargs)
  File "C:\Users\DELL\anaconda3\envs\Products_scraper\lib\site-packages\requests\api.py", line 59, in request
    return session.request(method=method, url=url, **kwargs)
  File "C:\Users\DELL\anaconda3\envs\Products_scraper\lib\site-packages\requests\sessions.py", line 587, in request
    resp = self.send(prep, **send_kwargs)
  File "C:\Users\DELL\anaconda3\envs\Products_scraper\lib\site-packages\requests\sessions.py", line 701, in send
    r = adapter.send(request, **kwargs)
  File "C:\Users\DELL\anaconda3\envs\Products_scraper\lib\site-packages\requests\adapters.py", line 553, in send
    raise ConnectTimeout(e, request=request)
requests.exceptions.ConnectTimeout: HTTPSConnectionPool(host='www.newegg.com', port=443): Max retries exceeded with url: /cerwin-vega-xls-215/p/0S6-00AA-00006?quicklink=true (Caused by ConnectTimeoutError(<urllib3.connection.HTTPSConnection object at 0x000001F645B882B0>, 'Connection to 89.107.197.165 timed out. (connect timeout=None)'))
urllib3.connectionpool:DEBUG:2022-10-03 16:40:53,463:Starting new HTTPS connection (1): www.newegg.com:443
root:ERROR:2022-10-03 16:41:14,598:HTTPSConnectionPool(host='www.newegg.com', port=443): Max retries exceeded with url: /cerwin-vega-xls-215/p/0S6-00AA-00006?quicklink=true (Caused by ConnectTimeoutError(<urllib3.connection.HTTPSConnection object at 0x000001F645784BE0>, 'Connection to 41.65.236.43 timed out. (connect timeout=None)'))
Traceback (most recent call last):
  File "C:\Users\DELL\anaconda3\envs\Products_scraper\lib\site-packages\urllib3\connection.py", line 174, in _new_conn
    conn = connection.create_connection(
  File "C:\Users\DELL\anaconda3\envs\Products_scraper\lib\site-packages\urllib3\util\connection.py", line 95, in create_connection
    raise err
  File "C:\Users\DELL\anaconda3\envs\Products_scraper\lib\site-packages\urllib3\util\connection.py", line 85, in create_connection
    sock.connect(sa)
TimeoutError: [WinError 10060] A connection attempt failed because the connected party did not properly respond after a period of time, or established connection failed because connected host has failed to respond

During handling of the above exception, another exception occurred:

Traceback (most recent call last):
  File "C:\Users\DELL\anaconda3\envs\Products_scraper\lib\site-packages\urllib3\connectionpool.py", line 700, in urlopen
    self._prepare_proxy(conn)
  File "C:\Users\DELL\anaconda3\envs\Products_scraper\lib\site-packages\urllib3\connectionpool.py", line 996, in _prepare_proxy
    conn.connect()
  File "C:\Users\DELL\anaconda3\envs\Products_scraper\lib\site-packages\urllib3\connection.py", line 358, in connect
    self.sock = conn = self._new_conn()
  File "C:\Users\DELL\anaconda3\envs\Products_scraper\lib\site-packages\urllib3\connection.py", line 179, in _new_conn
    raise ConnectTimeoutError(
urllib3.exceptions.ConnectTimeoutError: (<urllib3.connection.HTTPSConnection object at 0x000001F645784BE0>, 'Connection to 41.65.236.43 timed out. (connect timeout=None)')

During handling of the above exception, another exception occurred:

Traceback (most recent call last):
  File "C:\Users\DELL\anaconda3\envs\Products_scraper\lib\site-packages\requests\adapters.py", line 489, in send
    resp = conn.urlopen(
  File "C:\Users\DELL\anaconda3\envs\Products_scraper\lib\site-packages\urllib3\connectionpool.py", line 787, in urlopen
    retries = retries.increment(
  File "C:\Users\DELL\anaconda3\envs\Products_scraper\lib\site-packages\urllib3\util\retry.py", line 592, in increment
    raise MaxRetryError(_pool, url, error or ResponseError(cause))
urllib3.exceptions.MaxRetryError: HTTPSConnectionPool(host='www.newegg.com', port=443): Max retries exceeded with url: /cerwin-vega-xls-215/p/0S6-00AA-00006?quicklink=true (Caused by ConnectTimeoutError(<urllib3.connection.HTTPSConnection object at 0x000001F645784BE0>, 'Connection to 41.65.236.43 timed out. (connect timeout=None)'))

During handling of the above exception, another exception occurred:

Traceback (most recent call last):
  File "C:\Users\DELL\Desktop\Python work\Products_scraper\extractors\send_request.py", line 71, in send_request
    page = requests.get(url, headers=HEADERS, proxies=ip)
  File "C:\Users\DELL\anaconda3\envs\Products_scraper\lib\site-packages\requests\api.py", line 73, in get
    return request("get", url, params=params, **kwargs)
  File "C:\Users\DELL\anaconda3\envs\Products_scraper\lib\site-packages\requests\api.py", line 59, in request
    return session.request(method=method, url=url, **kwargs)
  File "C:\Users\DELL\anaconda3\envs\Products_scraper\lib\site-packages\requests\sessions.py", line 587, in request
    resp = self.send(prep, **send_kwargs)
  File "C:\Users\DELL\anaconda3\envs\Products_scraper\lib\site-packages\requests\sessions.py", line 701, in send
    r = adapter.send(request, **kwargs)
  File "C:\Users\DELL\anaconda3\envs\Products_scraper\lib\site-packages\requests\adapters.py", line 553, in send
    raise ConnectTimeout(e, request=request)
requests.exceptions.ConnectTimeout: HTTPSConnectionPool(host='www.newegg.com', port=443): Max retries exceeded with url: /cerwin-vega-xls-215/p/0S6-00AA-00006?quicklink=true (Caused by ConnectTimeoutError(<urllib3.connection.HTTPSConnection object at 0x000001F645784BE0>, 'Connection to 41.65.236.43 timed out. (connect timeout=None)'))
urllib3.connectionpool:DEBUG:2022-10-03 16:41:14,601:Starting new HTTPS connection (1): www.newegg.com:443
urllib3.connection:WARNING:2022-10-03 16:41:18,078:Certificate did not match expected hostname: www.newegg.com. Certificate: {'subject': ((('commonName', 'denied.shecan.ir'),),), 'issuer': ((('countryName', 'AT'),), (('organizationName', 'ZeroSSL'),), (('commonName', 'ZeroSSL RSA Domain Secure Site CA'),)), 'version': 3, 'serialNumber': 'F0AFB4D4D2FDD97201C4C3F2629A3AF0', 'notBefore': 'Sep  1 00:00:00 2022 GMT', 'notAfter': 'Nov 30 23:59:59 2022 GMT', 'subjectAltName': (('DNS', 'denied.shecan.ir'),), 'OCSP': ('http://zerossl.ocsp.sectigo.com',), 'caIssuers': ('http://zerossl.crt.sectigo.com/ZeroSSLRSADomainSecureSiteCA.crt',)}
root:ERROR:2022-10-03 16:41:18,078:HTTPSConnectionPool(host='www.newegg.com', port=443): Max retries exceeded with url: /cerwin-vega-xls-215/p/0S6-00AA-00006?quicklink=true (Caused by SSLError(CertificateError("hostname 'www.newegg.com' doesn't match 'denied.shecan.ir'")))
Traceback (most recent call last):
  File "C:\Users\DELL\anaconda3\envs\Products_scraper\lib\site-packages\urllib3\connectionpool.py", line 700, in urlopen
    self._prepare_proxy(conn)
  File "C:\Users\DELL\anaconda3\envs\Products_scraper\lib\site-packages\urllib3\connectionpool.py", line 996, in _prepare_proxy
    conn.connect()
  File "C:\Users\DELL\anaconda3\envs\Products_scraper\lib\site-packages\urllib3\connection.py", line 467, in connect
    _match_hostname(cert, self.assert_hostname or server_hostname)
  File "C:\Users\DELL\anaconda3\envs\Products_scraper\lib\site-packages\urllib3\connection.py", line 540, in _match_hostname
    match_hostname(cert, asserted_hostname)
  File "C:\Users\DELL\anaconda3\envs\Products_scraper\lib\site-packages\urllib3\util\ssl_match_hostname.py", line 155, in match_hostname
    raise CertificateError("hostname %r doesn't match %r" % (hostname, dnsnames[0]))
urllib3.util.ssl_match_hostname.CertificateError: hostname 'www.newegg.com' doesn't match 'denied.shecan.ir'

During handling of the above exception, another exception occurred:

Traceback (most recent call last):
  File "C:\Users\DELL\anaconda3\envs\Products_scraper\lib\site-packages\requests\adapters.py", line 489, in send
    resp = conn.urlopen(
  File "C:\Users\DELL\anaconda3\envs\Products_scraper\lib\site-packages\urllib3\connectionpool.py", line 787, in urlopen
    retries = retries.increment(
  File "C:\Users\DELL\anaconda3\envs\Products_scraper\lib\site-packages\urllib3\util\retry.py", line 592, in increment
    raise MaxRetryError(_pool, url, error or ResponseError(cause))
urllib3.exceptions.MaxRetryError: HTTPSConnectionPool(host='www.newegg.com', port=443): Max retries exceeded with url: /cerwin-vega-xls-215/p/0S6-00AA-00006?quicklink=true (Caused by SSLError(CertificateError("hostname 'www.newegg.com' doesn't match 'denied.shecan.ir'")))

During handling of the above exception, another exception occurred:

Traceback (most recent call last):
  File "C:\Users\DELL\Desktop\Python work\Products_scraper\extractors\send_request.py", line 71, in send_request
    page = requests.get(url, headers=HEADERS, proxies=ip)
  File "C:\Users\DELL\anaconda3\envs\Products_scraper\lib\site-packages\requests\api.py", line 73, in get
    return request("get", url, params=params, **kwargs)
  File "C:\Users\DELL\anaconda3\envs\Products_scraper\lib\site-packages\requests\api.py", line 59, in request
    return session.request(method=method, url=url, **kwargs)
  File "C:\Users\DELL\anaconda3\envs\Products_scraper\lib\site-packages\requests\sessions.py", line 587, in request
    resp = self.send(prep, **send_kwargs)
  File "C:\Users\DELL\anaconda3\envs\Products_scraper\lib\site-packages\requests\sessions.py", line 701, in send
    r = adapter.send(request, **kwargs)
  File "C:\Users\DELL\anaconda3\envs\Products_scraper\lib\site-packages\requests\adapters.py", line 563, in send
    raise SSLError(e, request=request)
requests.exceptions.SSLError: HTTPSConnectionPool(host='www.newegg.com', port=443): Max retries exceeded with url: /cerwin-vega-xls-215/p/0S6-00AA-00006?quicklink=true (Caused by SSLError(CertificateError("hostname 'www.newegg.com' doesn't match 'denied.shecan.ir'")))
urllib3.connectionpool:DEBUG:2022-10-03 16:41:18,086:Starting new HTTPS connection (1): www.newegg.com:443
urllib3.connectionpool:DEBUG:2022-10-03 16:41:29,428:https://www.newegg.com:443 "GET /cerwin-vega-xls-215/p/0S6-00AA-00006?quicklink=true HTTP/1.1" 200 25290
urllib3.connectionpool:DEBUG:2022-10-03 16:45:14,063:Starting new HTTPS connection (1): free-proxy-list.net:443
urllib3.connectionpool:DEBUG:2022-10-03 16:45:14,848:https://free-proxy-list.net:443 "GET / HTTP/1.1" 200 None
urllib3.connectionpool:DEBUG:2022-10-03 16:45:14,990:Starting new HTTPS connection (1): www.newegg.com:443
urllib3.connectionpool:DEBUG:2022-10-03 16:45:15,829:https://www.newegg.com:443 "GET /polk-audio-300367-14-00-005/p/N82E16886290064?quicklink=true HTTP/1.1" 200 29506
urllib3.connectionpool:DEBUG:2022-10-03 16:45:33,836:Starting new HTTPS connection (1): free-proxy-list.net:443
urllib3.connectionpool:DEBUG:2022-10-03 16:45:34,412:https://free-proxy-list.net:443 "GET / HTTP/1.1" 200 None
urllib3.connectionpool:DEBUG:2022-10-03 16:45:34,555:Starting new HTTPS connection (1): www.newegg.com:443
urllib3.connectionpool:DEBUG:2022-10-03 16:45:35,232:https://www.newegg.com:443 "GET /polk-audio-300367-14-00-005/p/N82E16886290064?quicklink=true HTTP/1.1" 200 29857
urllib3.connectionpool:DEBUG:2022-10-03 16:59:24,910:Starting new HTTPS connection (1): free-proxy-list.net:443
urllib3.connectionpool:DEBUG:2022-10-03 16:59:25,719:https://free-proxy-list.net:443 "GET / HTTP/1.1" 200 None
urllib3.connectionpool:DEBUG:2022-10-03 16:59:25,869:Starting new HTTPS connection (1): www.newegg.com:443
root:ERROR:2022-10-03 16:59:30,284:HTTPSConnectionPool(host='www.newegg.com', port=443): Max retries exceeded with url: /polk-audio-300367-14-00-005/p/N82E16886290064?quicklink=true (Caused by SSLError(SSLCertVerificationError(1, '[SSL: CERTIFICATE_VERIFY_FAILED] certificate verify failed: self signed certificate (_ssl.c:997)')))
Traceback (most recent call last):
  File "C:\Users\DELL\anaconda3\envs\Products_scraper\lib\site-packages\urllib3\connectionpool.py", line 700, in urlopen
    self._prepare_proxy(conn)
  File "C:\Users\DELL\anaconda3\envs\Products_scraper\lib\site-packages\urllib3\connectionpool.py", line 996, in _prepare_proxy
    conn.connect()
  File "C:\Users\DELL\anaconda3\envs\Products_scraper\lib\site-packages\urllib3\connection.py", line 414, in connect
    self.sock = ssl_wrap_socket(
  File "C:\Users\DELL\anaconda3\envs\Products_scraper\lib\site-packages\urllib3\util\ssl_.py", line 449, in ssl_wrap_socket
    ssl_sock = _ssl_wrap_socket_impl(
  File "C:\Users\DELL\anaconda3\envs\Products_scraper\lib\site-packages\urllib3\util\ssl_.py", line 493, in _ssl_wrap_socket_impl
    return ssl_context.wrap_socket(sock, server_hostname=server_hostname)
  File "C:\Users\DELL\anaconda3\envs\Products_scraper\lib\ssl.py", line 512, in wrap_socket
    return self.sslsocket_class._create(
  File "C:\Users\DELL\anaconda3\envs\Products_scraper\lib\ssl.py", line 1070, in _create
    self.do_handshake()
  File "C:\Users\DELL\anaconda3\envs\Products_scraper\lib\ssl.py", line 1341, in do_handshake
    self._sslobj.do_handshake()
ssl.SSLCertVerificationError: [SSL: CERTIFICATE_VERIFY_FAILED] certificate verify failed: self signed certificate (_ssl.c:997)

During handling of the above exception, another exception occurred:

Traceback (most recent call last):
  File "C:\Users\DELL\anaconda3\envs\Products_scraper\lib\site-packages\requests\adapters.py", line 489, in send
    resp = conn.urlopen(
  File "C:\Users\DELL\anaconda3\envs\Products_scraper\lib\site-packages\urllib3\connectionpool.py", line 787, in urlopen
    retries = retries.increment(
  File "C:\Users\DELL\anaconda3\envs\Products_scraper\lib\site-packages\urllib3\util\retry.py", line 592, in increment
    raise MaxRetryError(_pool, url, error or ResponseError(cause))
urllib3.exceptions.MaxRetryError: HTTPSConnectionPool(host='www.newegg.com', port=443): Max retries exceeded with url: /polk-audio-300367-14-00-005/p/N82E16886290064?quicklink=true (Caused by SSLError(SSLCertVerificationError(1, '[SSL: CERTIFICATE_VERIFY_FAILED] certificate verify failed: self signed certificate (_ssl.c:997)')))

During handling of the above exception, another exception occurred:

Traceback (most recent call last):
  File "C:\Users\DELL\Desktop\Python work\Products_scraper\extractors\send_request.py", line 71, in send_request
    page = requests.get(url, headers=HEADERS, proxies=ip)
  File "C:\Users\DELL\anaconda3\envs\Products_scraper\lib\site-packages\requests\api.py", line 73, in get
    return request("get", url, params=params, **kwargs)
  File "C:\Users\DELL\anaconda3\envs\Products_scraper\lib\site-packages\requests\api.py", line 59, in request
    return session.request(method=method, url=url, **kwargs)
  File "C:\Users\DELL\anaconda3\envs\Products_scraper\lib\site-packages\requests\sessions.py", line 587, in request
    resp = self.send(prep, **send_kwargs)
  File "C:\Users\DELL\anaconda3\envs\Products_scraper\lib\site-packages\requests\sessions.py", line 701, in send
    r = adapter.send(request, **kwargs)
  File "C:\Users\DELL\anaconda3\envs\Products_scraper\lib\site-packages\requests\adapters.py", line 563, in send
    raise SSLError(e, request=request)
requests.exceptions.SSLError: HTTPSConnectionPool(host='www.newegg.com', port=443): Max retries exceeded with url: /polk-audio-300367-14-00-005/p/N82E16886290064?quicklink=true (Caused by SSLError(SSLCertVerificationError(1, '[SSL: CERTIFICATE_VERIFY_FAILED] certificate verify failed: self signed certificate (_ssl.c:997)')))
urllib3.connectionpool:DEBUG:2022-10-03 16:59:30,372:Starting new HTTPS connection (1): www.newegg.com:443
urllib3.connectionpool:DEBUG:2022-10-03 16:59:31,080:https://www.newegg.com:443 "GET /polk-audio-300367-14-00-005/p/N82E16886290064?quicklink=true HTTP/1.1" 200 29857
urllib3.connectionpool:DEBUG:2022-10-03 17:10:20,013:Starting new HTTPS connection (1): free-proxy-list.net:443
urllib3.connectionpool:DEBUG:2022-10-03 17:10:20,724:https://free-proxy-list.net:443 "GET / HTTP/1.1" 200 None
urllib3.connectionpool:DEBUG:2022-10-03 17:10:20,977:Starting new HTTPS connection (1): www.newegg.com:443
root:ERROR:2022-10-03 17:10:25,736:HTTPSConnectionPool(host='www.newegg.com', port=443): Max retries exceeded with url: /p/pl?N=100008225%20600030002 (Caused by SSLError(SSLCertVerificationError(1, '[SSL: CERTIFICATE_VERIFY_FAILED] certificate verify failed: self signed certificate (_ssl.c:997)')))
Traceback (most recent call last):
  File "C:\Users\DELL\anaconda3\envs\Products_scraper\lib\site-packages\urllib3\connectionpool.py", line 700, in urlopen
    self._prepare_proxy(conn)
  File "C:\Users\DELL\anaconda3\envs\Products_scraper\lib\site-packages\urllib3\connectionpool.py", line 996, in _prepare_proxy
    conn.connect()
  File "C:\Users\DELL\anaconda3\envs\Products_scraper\lib\site-packages\urllib3\connection.py", line 414, in connect
    self.sock = ssl_wrap_socket(
  File "C:\Users\DELL\anaconda3\envs\Products_scraper\lib\site-packages\urllib3\util\ssl_.py", line 449, in ssl_wrap_socket
    ssl_sock = _ssl_wrap_socket_impl(
  File "C:\Users\DELL\anaconda3\envs\Products_scraper\lib\site-packages\urllib3\util\ssl_.py", line 493, in _ssl_wrap_socket_impl
    return ssl_context.wrap_socket(sock, server_hostname=server_hostname)
  File "C:\Users\DELL\anaconda3\envs\Products_scraper\lib\ssl.py", line 512, in wrap_socket
    return self.sslsocket_class._create(
  File "C:\Users\DELL\anaconda3\envs\Products_scraper\lib\ssl.py", line 1070, in _create
    self.do_handshake()
  File "C:\Users\DELL\anaconda3\envs\Products_scraper\lib\ssl.py", line 1341, in do_handshake
    self._sslobj.do_handshake()
ssl.SSLCertVerificationError: [SSL: CERTIFICATE_VERIFY_FAILED] certificate verify failed: self signed certificate (_ssl.c:997)

During handling of the above exception, another exception occurred:

Traceback (most recent call last):
  File "C:\Users\DELL\anaconda3\envs\Products_scraper\lib\site-packages\requests\adapters.py", line 489, in send
    resp = conn.urlopen(
  File "C:\Users\DELL\anaconda3\envs\Products_scraper\lib\site-packages\urllib3\connectionpool.py", line 787, in urlopen
    retries = retries.increment(
  File "C:\Users\DELL\anaconda3\envs\Products_scraper\lib\site-packages\urllib3\util\retry.py", line 592, in increment
    raise MaxRetryError(_pool, url, error or ResponseError(cause))
urllib3.exceptions.MaxRetryError: HTTPSConnectionPool(host='www.newegg.com', port=443): Max retries exceeded with url: /p/pl?N=100008225%20600030002 (Caused by SSLError(SSLCertVerificationError(1, '[SSL: CERTIFICATE_VERIFY_FAILED] certificate verify failed: self signed certificate (_ssl.c:997)')))

During handling of the above exception, another exception occurred:

Traceback (most recent call last):
  File "C:\Users\DELL\Desktop\Python work\Products_scraper\extractors\send_request.py", line 71, in send_request
    page = requests.get(url, headers=HEADERS, proxies=ip)
  File "C:\Users\DELL\anaconda3\envs\Products_scraper\lib\site-packages\requests\api.py", line 73, in get
    return request("get", url, params=params, **kwargs)
  File "C:\Users\DELL\anaconda3\envs\Products_scraper\lib\site-packages\requests\api.py", line 59, in request
    return session.request(method=method, url=url, **kwargs)
  File "C:\Users\DELL\anaconda3\envs\Products_scraper\lib\site-packages\requests\sessions.py", line 587, in request
    resp = self.send(prep, **send_kwargs)
  File "C:\Users\DELL\anaconda3\envs\Products_scraper\lib\site-packages\requests\sessions.py", line 701, in send
    r = adapter.send(request, **kwargs)
  File "C:\Users\DELL\anaconda3\envs\Products_scraper\lib\site-packages\requests\adapters.py", line 563, in send
    raise SSLError(e, request=request)
requests.exceptions.SSLError: HTTPSConnectionPool(host='www.newegg.com', port=443): Max retries exceeded with url: /p/pl?N=100008225%20600030002 (Caused by SSLError(SSLCertVerificationError(1, '[SSL: CERTIFICATE_VERIFY_FAILED] certificate verify failed: self signed certificate (_ssl.c:997)')))
urllib3.connectionpool:DEBUG:2022-10-03 17:10:25,773:Starting new HTTPS connection (1): www.newegg.com:443
urllib3.connectionpool:DEBUG:2022-10-03 17:10:26,778:https://www.newegg.com:443 "GET /p/pl?N=100008225%20600030002 HTTP/1.1" 200 67237
root:INFO:2022-10-03 17:10:26,963:No product id.
root:INFO:2022-10-03 17:10:26,970:No title.
urllib3.connectionpool:DEBUG:2022-10-03 17:10:39,227:Starting new HTTPS connection (1): free-proxy-list.net:443
urllib3.connectionpool:DEBUG:2022-10-03 17:10:39,845:https://free-proxy-list.net:443 "GET / HTTP/1.1" 200 None
urllib3.connectionpool:DEBUG:2022-10-03 17:10:40,151:Starting new HTTPS connection (1): www.newegg.com:443
urllib3.connectionpool:DEBUG:2022-10-03 17:10:40,507:https://www.newegg.com:443 "GET /cerwin-vega-xls-215/p/0S6-00AA-00006?quicklink=true HTTP/1.1" 200 25290
urllib3.connectionpool:DEBUG:2022-10-03 17:10:59,084:Starting new HTTPS connection (1): free-proxy-list.net:443
urllib3.connectionpool:DEBUG:2022-10-03 17:10:59,603:https://free-proxy-list.net:443 "GET / HTTP/1.1" 200 None
urllib3.connectionpool:DEBUG:2022-10-03 17:10:59,738:Starting new HTTPS connection (1): www.newegg.com:443
root:ERROR:2022-10-03 17:11:04,055:HTTPSConnectionPool(host='www.newegg.com', port=443): Max retries exceeded with url: /cerwin-vega-xls-215/p/0S6-00AA-00006?quicklink=true (Caused by SSLError(SSLCertVerificationError(1, '[SSL: CERTIFICATE_VERIFY_FAILED] certificate verify failed: self signed certificate (_ssl.c:997)')))
Traceback (most recent call last):
  File "C:\Users\DELL\anaconda3\envs\Products_scraper\lib\site-packages\urllib3\connectionpool.py", line 700, in urlopen
    self._prepare_proxy(conn)
  File "C:\Users\DELL\anaconda3\envs\Products_scraper\lib\site-packages\urllib3\connectionpool.py", line 996, in _prepare_proxy
    conn.connect()
  File "C:\Users\DELL\anaconda3\envs\Products_scraper\lib\site-packages\urllib3\connection.py", line 414, in connect
    self.sock = ssl_wrap_socket(
  File "C:\Users\DELL\anaconda3\envs\Products_scraper\lib\site-packages\urllib3\util\ssl_.py", line 449, in ssl_wrap_socket
    ssl_sock = _ssl_wrap_socket_impl(
  File "C:\Users\DELL\anaconda3\envs\Products_scraper\lib\site-packages\urllib3\util\ssl_.py", line 493, in _ssl_wrap_socket_impl
    return ssl_context.wrap_socket(sock, server_hostname=server_hostname)
  File "C:\Users\DELL\anaconda3\envs\Products_scraper\lib\ssl.py", line 512, in wrap_socket
    return self.sslsocket_class._create(
  File "C:\Users\DELL\anaconda3\envs\Products_scraper\lib\ssl.py", line 1070, in _create
    self.do_handshake()
  File "C:\Users\DELL\anaconda3\envs\Products_scraper\lib\ssl.py", line 1341, in do_handshake
    self._sslobj.do_handshake()
ssl.SSLCertVerificationError: [SSL: CERTIFICATE_VERIFY_FAILED] certificate verify failed: self signed certificate (_ssl.c:997)

During handling of the above exception, another exception occurred:

Traceback (most recent call last):
  File "C:\Users\DELL\anaconda3\envs\Products_scraper\lib\site-packages\requests\adapters.py", line 489, in send
    resp = conn.urlopen(
  File "C:\Users\DELL\anaconda3\envs\Products_scraper\lib\site-packages\urllib3\connectionpool.py", line 787, in urlopen
    retries = retries.increment(
  File "C:\Users\DELL\anaconda3\envs\Products_scraper\lib\site-packages\urllib3\util\retry.py", line 592, in increment
    raise MaxRetryError(_pool, url, error or ResponseError(cause))
urllib3.exceptions.MaxRetryError: HTTPSConnectionPool(host='www.newegg.com', port=443): Max retries exceeded with url: /cerwin-vega-xls-215/p/0S6-00AA-00006?quicklink=true (Caused by SSLError(SSLCertVerificationError(1, '[SSL: CERTIFICATE_VERIFY_FAILED] certificate verify failed: self signed certificate (_ssl.c:997)')))

During handling of the above exception, another exception occurred:

Traceback (most recent call last):
  File "C:\Users\DELL\Desktop\Python work\Products_scraper\extractors\send_request.py", line 71, in send_request
    page = requests.get(url, headers=HEADERS, proxies=ip)
  File "C:\Users\DELL\anaconda3\envs\Products_scraper\lib\site-packages\requests\api.py", line 73, in get
    return request("get", url, params=params, **kwargs)
  File "C:\Users\DELL\anaconda3\envs\Products_scraper\lib\site-packages\requests\api.py", line 59, in request
    return session.request(method=method, url=url, **kwargs)
  File "C:\Users\DELL\anaconda3\envs\Products_scraper\lib\site-packages\requests\sessions.py", line 587, in request
    resp = self.send(prep, **send_kwargs)
  File "C:\Users\DELL\anaconda3\envs\Products_scraper\lib\site-packages\requests\sessions.py", line 701, in send
    r = adapter.send(request, **kwargs)
  File "C:\Users\DELL\anaconda3\envs\Products_scraper\lib\site-packages\requests\adapters.py", line 563, in send
    raise SSLError(e, request=request)
requests.exceptions.SSLError: HTTPSConnectionPool(host='www.newegg.com', port=443): Max retries exceeded with url: /cerwin-vega-xls-215/p/0S6-00AA-00006?quicklink=true (Caused by SSLError(SSLCertVerificationError(1, '[SSL: CERTIFICATE_VERIFY_FAILED] certificate verify failed: self signed certificate (_ssl.c:997)')))
urllib3.connectionpool:DEBUG:2022-10-03 17:11:04,083:Starting new HTTPS connection (1): www.newegg.com:443
urllib3.connectionpool:DEBUG:2022-10-03 17:11:04,452:https://www.newegg.com:443 "GET /cerwin-vega-xls-215/p/0S6-00AA-00006?quicklink=true HTTP/1.1" 200 25290
urllib3.connectionpool:DEBUG:2022-10-03 17:16:37,488:Starting new HTTPS connection (1): free-proxy-list.net:443
urllib3.connectionpool:DEBUG:2022-10-03 17:16:38,205:https://free-proxy-list.net:443 "GET / HTTP/1.1" 200 None
urllib3.connectionpool:DEBUG:2022-10-03 17:16:38,477:Starting new HTTPS connection (1): www.newegg.com:443
urllib3.connectionpool:DEBUG:2022-10-03 17:16:38,865:https://www.newegg.com:443 "GET /cerwin-vega-xls-215/p/0S6-00AA-00006?quicklink=true HTTP/1.1" 200 25290
urllib3.connectionpool:DEBUG:2022-10-03 17:17:26,812:Starting new HTTPS connection (1): free-proxy-list.net:443
urllib3.connectionpool:DEBUG:2022-10-03 17:17:27,476:https://free-proxy-list.net:443 "GET / HTTP/1.1" 200 None
urllib3.connectionpool:DEBUG:2022-10-03 17:17:27,632:Starting new HTTPS connection (1): www.newegg.com:443
urllib3.connectionpool:DEBUG:2022-10-03 17:17:28,120:https://www.newegg.com:443 "GET /creality-ender-3-v2-black/p/288-00DY-00001 HTTP/1.1" 200 43611
urllib3.connectionpool:DEBUG:2022-10-03 17:18:22,114:Starting new HTTPS connection (1): free-proxy-list.net:443
urllib3.connectionpool:DEBUG:2022-10-03 17:18:22,793:https://free-proxy-list.net:443 "GET / HTTP/1.1" 200 None
urllib3.connectionpool:DEBUG:2022-10-03 17:18:22,939:Starting new HTTPS connection (1): www.newegg.com:443
urllib3.connectionpool:DEBUG:2022-10-03 17:18:23,541:https://www.newegg.com:443 "GET /creality-ender-3-v2-black/p/288-00DY-00001 HTTP/1.1" 200 43584
urllib3.connectionpool:DEBUG:2022-10-03 17:18:51,743:Starting new HTTPS connection (1): free-proxy-list.net:443
urllib3.connectionpool:DEBUG:2022-10-03 17:18:52,423:https://free-proxy-list.net:443 "GET / HTTP/1.1" 200 None
urllib3.connectionpool:DEBUG:2022-10-03 17:18:52,569:Starting new HTTPS connection (1): www.newegg.com:443
urllib3.connectionpool:DEBUG:2022-10-03 17:18:53,490:https://www.newegg.com:443 "GET /creality-ender-3-v2-black/p/288-00DY-00001 HTTP/1.1" 200 43586
urllib3.connectionpool:DEBUG:2022-10-03 17:19:12,619:Starting new HTTPS connection (1): free-proxy-list.net:443
urllib3.connectionpool:DEBUG:2022-10-03 17:19:13,139:https://free-proxy-list.net:443 "GET / HTTP/1.1" 200 None
urllib3.connectionpool:DEBUG:2022-10-03 17:19:13,281:Starting new HTTPS connection (1): www.newegg.com:443
urllib3.connectionpool:DEBUG:2022-10-03 17:19:13,778:https://www.newegg.com:443 "GET /creality-ender-3-v2-black/p/288-00DY-00001 HTTP/1.1" 200 43595
urllib3.connectionpool:DEBUG:2022-10-03 17:19:26,440:Starting new HTTPS connection (1): free-proxy-list.net:443
urllib3.connectionpool:DEBUG:2022-10-03 17:19:27,034:https://free-proxy-list.net:443 "GET / HTTP/1.1" 200 None
urllib3.connectionpool:DEBUG:2022-10-03 17:19:27,174:Starting new HTTPS connection (1): www.newegg.com:443
urllib3.connectionpool:DEBUG:2022-10-03 17:19:27,642:https://www.newegg.com:443 "GET /creality-ender-3-v2-black/p/288-00DY-00001 HTTP/1.1" 200 43598
urllib3.connectionpool:DEBUG:2022-10-03 17:19:46,749:Starting new HTTPS connection (1): free-proxy-list.net:443
urllib3.connectionpool:DEBUG:2022-10-03 17:19:47,313:https://free-proxy-list.net:443 "GET / HTTP/1.1" 200 None
urllib3.connectionpool:DEBUG:2022-10-03 17:19:47,450:Starting new HTTPS connection (1): www.newegg.com:443
urllib3.connectionpool:DEBUG:2022-10-03 17:19:47,825:https://www.newegg.com:443 "GET /creality-ender-3-v2-black/p/288-00DY-00001 HTTP/1.1" 200 43595
urllib3.connectionpool:DEBUG:2022-10-03 23:10:40,236:Starting new HTTPS connection (1): free-proxy-list.net:443
urllib3.connectionpool:DEBUG:2022-10-03 23:10:41,032:https://free-proxy-list.net:443 "GET / HTTP/1.1" 200 None
urllib3.connectionpool:DEBUG:2022-10-03 23:10:41,346:Starting new HTTPS connection (1): www.newegg.com:443
urllib3.connectionpool:DEBUG:2022-10-03 23:10:42,445:https://www.newegg.com:443 "GET /p/pl?N=100008225%20600030002 HTTP/1.1" 200 None
urllib3.connectionpool:DEBUG:2022-10-04 21:34:27,731:Starting new HTTPS connection (1): free-proxy-list.net:443
urllib3.connectionpool:DEBUG:2022-10-04 21:34:28,552:https://free-proxy-list.net:443 "GET / HTTP/1.1" 200 None
urllib3.connectionpool:DEBUG:2022-10-04 21:34:28,704:Starting new HTTPS connection (1): www.bestbuy.com:443
urllib3.connectionpool:DEBUG:2022-10-04 21:36:44,221:Starting new HTTPS connection (1): www.bestbuy.com:443
urllib3.connectionpool:DEBUG:2022-10-04 21:36:44,900:https://www.bestbuy.com:443 "GET /site/speakers/floor-speakers/abcat0205003.c?id=abcat0205003 HTTP/1.1" 403 333
charset_normalizer:DEBUG:2022-10-04 21:36:44,912:Encoding detection: ascii is most likely the one.
urllib3.connectionpool:DEBUG:2022-10-04 21:37:03,448:Starting new HTTPS connection (1): www.bestbuy.com:443
urllib3.connectionpool:DEBUG:2022-10-04 21:37:03,711:https://www.bestbuy.com:443 "GET /site/speakers/floor-speakers/abcat0205003.c?id=abcat0205003 HTTP/1.1" 403 332
charset_normalizer:DEBUG:2022-10-04 21:37:03,720:Encoding detection: ascii is most likely the one.
urllib3.connectionpool:DEBUG:2022-10-04 21:43:49,438:Starting new HTTPS connection (1): free-proxy-list.net:443
urllib3.connectionpool:DEBUG:2022-10-04 21:43:50,074:https://free-proxy-list.net:443 "GET / HTTP/1.1" 200 None
urllib3.connectionpool:DEBUG:2022-10-04 21:43:50,304:Starting new HTTPS connection (1): www.costco.com:443
urllib3.connectionpool:DEBUG:2022-10-04 21:45:21,126:Starting new HTTPS connection (1): www.costco.com:443
urllib3.connectionpool:DEBUG:2022-10-04 21:48:24,499:Starting new HTTPS connection (1): www.costco.com:443
urllib3.connectionpool:DEBUG:2022-10-04 21:54:05,629:Starting new HTTPS connection (1): www.google.com:443
urllib3.connectionpool:DEBUG:2022-10-04 21:54:05,919:https://www.google.com:443 "GET / HTTP/1.1" 200 None
urllib3.connectionpool:DEBUG:2022-10-04 21:55:28,113:Starting new HTTPS connection (1): www.costco.com:443
urllib3.connectionpool:DEBUG:2022-10-04 21:55:54,638:Starting new HTTPS connection (1): www.costco.com:443
urllib3.connectionpool:DEBUG:2022-10-04 21:56:42,062:Starting new HTTPS connection (1): www.bestbuy.com:443
urllib3.connectionpool:DEBUG:2022-10-04 22:00:47,593:Starting new HTTPS connection (1): www.bestbuy.com:443
urllib3.connectionpool:DEBUG:2022-10-04 22:01:07,277:Starting new HTTPS connection (1): www.bestbuy.com:443
urllib3.connectionpool:DEBUG:2022-10-04 22:03:39,116:Starting new HTTPS connection (1): www.bestbuy.com:443
urllib3.connectionpool:DEBUG:2022-10-04 22:04:04,343:Starting new HTTPS connection (1): www.costco.com:443
urllib3.connectionpool:DEBUG:2022-10-04 22:04:46,695:Starting new HTTPS connection (1): www.costco.com:443
urllib3.connectionpool:DEBUG:2022-10-04 22:04:47,423:https://www.costco.com:443 "GET / HTTP/1.1" 200 None
urllib3.connectionpool:DEBUG:2022-10-04 22:07:07,260:Starting new HTTPS connection (1): free-proxy-list.net:443
urllib3.connectionpool:DEBUG:2022-10-04 22:07:07,873:https://free-proxy-list.net:443 "GET / HTTP/1.1" 200 None
urllib3.connectionpool:DEBUG:2022-10-04 22:07:08,160:Starting new HTTPS connection (1): www.costco.com:443
urllib3.connectionpool:DEBUG:2022-10-04 22:07:10,067:https://www.costco.com:443 "GET /home-theater-systems.html HTTP/1.1" 200 None
urllib3.connectionpool:DEBUG:2022-10-04 22:08:00,622:Starting new HTTPS connection (1): free-proxy-list.net:443
urllib3.connectionpool:DEBUG:2022-10-04 22:08:01,165:https://free-proxy-list.net:443 "GET / HTTP/1.1" 200 None
urllib3.connectionpool:DEBUG:2022-10-04 22:08:01,308:Starting new HTTPS connection (1): www.costco.com:443
urllib3.connectionpool:DEBUG:2022-10-04 22:08:02,294:https://www.costco.com:443 "GET /home-theater-systems.html HTTP/1.1" 200 None
urllib3.connectionpool:DEBUG:2022-10-04 22:08:32,719:Starting new HTTPS connection (1): free-proxy-list.net:443
urllib3.connectionpool:DEBUG:2022-10-04 22:08:33,231:https://free-proxy-list.net:443 "GET / HTTP/1.1" 200 None
urllib3.connectionpool:DEBUG:2022-10-04 22:08:33,508:Starting new HTTPS connection (1): www.bestbuy.com:443
urllib3.connectionpool:DEBUG:2022-10-04 22:08:33,713:https://www.bestbuy.com:443 "GET /site/speakers/floor-speakers/abcat0205003.c?id=abcat0205003 HTTP/1.1" 200 1659
urllib3.connectionpool:DEBUG:2022-10-04 22:09:02,045:Starting new HTTPS connection (1): free-proxy-list.net:443
urllib3.connectionpool:DEBUG:2022-10-04 22:09:02,634:https://free-proxy-list.net:443 "GET / HTTP/1.1" 200 None
urllib3.connectionpool:DEBUG:2022-10-04 22:09:02,780:Starting new HTTPS connection (1): www.bestbuy.com:443
urllib3.connectionpool:DEBUG:2022-10-04 22:09:03,480:https://www.bestbuy.com:443 "GET /site/speakers/floor-speakers/abcat0205003.c?id=abcat0205003 HTTP/1.1" 200 1659
urllib3.connectionpool:DEBUG:2022-10-04 22:10:24,842:Starting new HTTPS connection (1): free-proxy-list.net:443
urllib3.connectionpool:DEBUG:2022-10-04 22:10:25,365:https://free-proxy-list.net:443 "GET / HTTP/1.1" 200 None
urllib3.connectionpool:DEBUG:2022-10-04 22:10:25,517:Starting new HTTPS connection (1): www.bestbuy.com:443
urllib3.connectionpool:DEBUG:2022-10-04 22:10:25,669:https://www.bestbuy.com:443 "GET /site/speakers/floor-speakers/abcat0205003.c?id=abcat0205003 HTTP/1.1" 200 1659
urllib3.connectionpool:DEBUG:2022-10-04 22:11:01,989:Starting new HTTPS connection (1): free-proxy-list.net:443
urllib3.connectionpool:DEBUG:2022-10-04 22:11:02,500:https://free-proxy-list.net:443 "GET / HTTP/1.1" 200 None
urllib3.connectionpool:DEBUG:2022-10-04 22:11:02,675:Starting new HTTPS connection (1): www.bestbuy.com:443
urllib3.connectionpool:DEBUG:2022-10-04 22:11:03,413:https://www.bestbuy.com:443 "GET /site/speakers/floor-speakers/abcat0205003.c?id=abcat0205003 HTTP/1.1" 200 1659
urllib3.connectionpool:DEBUG:2022-10-04 22:11:26,778:Starting new HTTPS connection (1): free-proxy-list.net:443
urllib3.connectionpool:DEBUG:2022-10-04 22:11:27,267:https://free-proxy-list.net:443 "GET / HTTP/1.1" 200 None
urllib3.connectionpool:DEBUG:2022-10-04 22:11:27,398:Starting new HTTPS connection (1): www.bestbuy.com:443
urllib3.connectionpool:DEBUG:2022-10-04 22:11:27,527:https://www.bestbuy.com:443 "GET /site/speakers/floor-speakers/abcat0205003.c?id=abcat0205003 HTTP/1.1" 200 1659
urllib3.connectionpool:DEBUG:2022-10-04 22:13:58,350:Starting new HTTPS connection (1): free-proxy-list.net:443
urllib3.connectionpool:DEBUG:2022-10-04 22:13:58,896:https://free-proxy-list.net:443 "GET / HTTP/1.1" 200 None
urllib3.connectionpool:DEBUG:2022-10-04 22:13:59,039:Starting new HTTPS connection (1): www.bestbuy.com:443
urllib3.connectionpool:DEBUG:2022-10-04 22:14:39,816:Starting new HTTPS connection (1): free-proxy-list.net:443
urllib3.connectionpool:DEBUG:2022-10-04 22:14:40,450:https://free-proxy-list.net:443 "GET / HTTP/1.1" 200 None
urllib3.connectionpool:DEBUG:2022-10-04 22:14:40,577:Starting new HTTPS connection (1): www.bestbuy.com:443
root:ERROR:2022-10-04 22:14:40,848:HTTPSConnectionPool(host='www.bestbuy.com', port=443): Max retries exceeded with url: /site/speakers/floor-speakers/abcat0205003.c?id=abcat0205003&page=2 (Caused by ProxyError('Cannot connect to proxy.', ConnectionResetError(10054, 'An existing connection was forcibly closed by the remote host', None, 10054, None)))
Traceback (most recent call last):
  File "C:\Users\DELL\anaconda3\envs\Products_scraper\lib\site-packages\urllib3\connectionpool.py", line 700, in urlopen
    self._prepare_proxy(conn)
  File "C:\Users\DELL\anaconda3\envs\Products_scraper\lib\site-packages\urllib3\connectionpool.py", line 996, in _prepare_proxy
    conn.connect()
  File "C:\Users\DELL\anaconda3\envs\Products_scraper\lib\site-packages\urllib3\connection.py", line 369, in connect
    self._tunnel()
  File "C:\Users\DELL\anaconda3\envs\Products_scraper\lib\http\client.py", line 920, in _tunnel
    (version, code, message) = response._read_status()
  File "C:\Users\DELL\anaconda3\envs\Products_scraper\lib\http\client.py", line 279, in _read_status
    line = str(self.fp.readline(_MAXLINE + 1), "iso-8859-1")
  File "C:\Users\DELL\anaconda3\envs\Products_scraper\lib\socket.py", line 705, in readinto
    return self._sock.recv_into(b)
ConnectionResetError: [WinError 10054] An existing connection was forcibly closed by the remote host

During handling of the above exception, another exception occurred:

Traceback (most recent call last):
  File "C:\Users\DELL\anaconda3\envs\Products_scraper\lib\site-packages\requests\adapters.py", line 489, in send
    resp = conn.urlopen(
  File "C:\Users\DELL\anaconda3\envs\Products_scraper\lib\site-packages\urllib3\connectionpool.py", line 787, in urlopen
    retries = retries.increment(
  File "C:\Users\DELL\anaconda3\envs\Products_scraper\lib\site-packages\urllib3\util\retry.py", line 592, in increment
    raise MaxRetryError(_pool, url, error or ResponseError(cause))
urllib3.exceptions.MaxRetryError: HTTPSConnectionPool(host='www.bestbuy.com', port=443): Max retries exceeded with url: /site/speakers/floor-speakers/abcat0205003.c?id=abcat0205003&page=2 (Caused by ProxyError('Cannot connect to proxy.', ConnectionResetError(10054, 'An existing connection was forcibly closed by the remote host', None, 10054, None)))

During handling of the above exception, another exception occurred:

Traceback (most recent call last):
  File "C:\Users\DELL\Desktop\Python work\Products_scraper\extractors\send_request.py", line 75, in send_request
    page = requests.get(url, headers=headers, proxies=ip)
  File "C:\Users\DELL\anaconda3\envs\Products_scraper\lib\site-packages\requests\api.py", line 73, in get
    return request("get", url, params=params, **kwargs)
  File "C:\Users\DELL\anaconda3\envs\Products_scraper\lib\site-packages\requests\api.py", line 59, in request
    return session.request(method=method, url=url, **kwargs)
  File "C:\Users\DELL\anaconda3\envs\Products_scraper\lib\site-packages\requests\sessions.py", line 587, in request
    resp = self.send(prep, **send_kwargs)
  File "C:\Users\DELL\anaconda3\envs\Products_scraper\lib\site-packages\requests\sessions.py", line 701, in send
    r = adapter.send(request, **kwargs)
  File "C:\Users\DELL\anaconda3\envs\Products_scraper\lib\site-packages\requests\adapters.py", line 559, in send
    raise ProxyError(e, request=request)
requests.exceptions.ProxyError: HTTPSConnectionPool(host='www.bestbuy.com', port=443): Max retries exceeded with url: /site/speakers/floor-speakers/abcat0205003.c?id=abcat0205003&page=2 (Caused by ProxyError('Cannot connect to proxy.', ConnectionResetError(10054, 'An existing connection was forcibly closed by the remote host', None, 10054, None)))
urllib3.connectionpool:DEBUG:2022-10-04 22:14:40,883:Starting new HTTPS connection (1): www.bestbuy.com:443
root:ERROR:2022-10-04 22:14:45,402:HTTPSConnectionPool(host='www.bestbuy.com', port=443): Max retries exceeded with url: /site/speakers/floor-speakers/abcat0205003.c?id=abcat0205003&page=2 (Caused by SSLError(SSLCertVerificationError(1, '[SSL: CERTIFICATE_VERIFY_FAILED] certificate verify failed: self signed certificate (_ssl.c:997)')))
Traceback (most recent call last):
  File "C:\Users\DELL\anaconda3\envs\Products_scraper\lib\site-packages\urllib3\connectionpool.py", line 700, in urlopen
    self._prepare_proxy(conn)
  File "C:\Users\DELL\anaconda3\envs\Products_scraper\lib\site-packages\urllib3\connectionpool.py", line 996, in _prepare_proxy
    conn.connect()
  File "C:\Users\DELL\anaconda3\envs\Products_scraper\lib\site-packages\urllib3\connection.py", line 414, in connect
    self.sock = ssl_wrap_socket(
  File "C:\Users\DELL\anaconda3\envs\Products_scraper\lib\site-packages\urllib3\util\ssl_.py", line 449, in ssl_wrap_socket
    ssl_sock = _ssl_wrap_socket_impl(
  File "C:\Users\DELL\anaconda3\envs\Products_scraper\lib\site-packages\urllib3\util\ssl_.py", line 493, in _ssl_wrap_socket_impl
    return ssl_context.wrap_socket(sock, server_hostname=server_hostname)
  File "C:\Users\DELL\anaconda3\envs\Products_scraper\lib\ssl.py", line 512, in wrap_socket
    return self.sslsocket_class._create(
  File "C:\Users\DELL\anaconda3\envs\Products_scraper\lib\ssl.py", line 1070, in _create
    self.do_handshake()
  File "C:\Users\DELL\anaconda3\envs\Products_scraper\lib\ssl.py", line 1341, in do_handshake
    self._sslobj.do_handshake()
ssl.SSLCertVerificationError: [SSL: CERTIFICATE_VERIFY_FAILED] certificate verify failed: self signed certificate (_ssl.c:997)

During handling of the above exception, another exception occurred:

Traceback (most recent call last):
  File "C:\Users\DELL\anaconda3\envs\Products_scraper\lib\site-packages\requests\adapters.py", line 489, in send
    resp = conn.urlopen(
  File "C:\Users\DELL\anaconda3\envs\Products_scraper\lib\site-packages\urllib3\connectionpool.py", line 787, in urlopen
    retries = retries.increment(
  File "C:\Users\DELL\anaconda3\envs\Products_scraper\lib\site-packages\urllib3\util\retry.py", line 592, in increment
    raise MaxRetryError(_pool, url, error or ResponseError(cause))
urllib3.exceptions.MaxRetryError: HTTPSConnectionPool(host='www.bestbuy.com', port=443): Max retries exceeded with url: /site/speakers/floor-speakers/abcat0205003.c?id=abcat0205003&page=2 (Caused by SSLError(SSLCertVerificationError(1, '[SSL: CERTIFICATE_VERIFY_FAILED] certificate verify failed: self signed certificate (_ssl.c:997)')))

During handling of the above exception, another exception occurred:

Traceback (most recent call last):
  File "C:\Users\DELL\Desktop\Python work\Products_scraper\extractors\send_request.py", line 75, in send_request
    page = requests.get(url, headers=headers, proxies=ip)
  File "C:\Users\DELL\anaconda3\envs\Products_scraper\lib\site-packages\requests\api.py", line 73, in get
    return request("get", url, params=params, **kwargs)
  File "C:\Users\DELL\anaconda3\envs\Products_scraper\lib\site-packages\requests\api.py", line 59, in request
    return session.request(method=method, url=url, **kwargs)
  File "C:\Users\DELL\anaconda3\envs\Products_scraper\lib\site-packages\requests\sessions.py", line 587, in request
    resp = self.send(prep, **send_kwargs)
  File "C:\Users\DELL\anaconda3\envs\Products_scraper\lib\site-packages\requests\sessions.py", line 701, in send
    r = adapter.send(request, **kwargs)
  File "C:\Users\DELL\anaconda3\envs\Products_scraper\lib\site-packages\requests\adapters.py", line 563, in send
    raise SSLError(e, request=request)
requests.exceptions.SSLError: HTTPSConnectionPool(host='www.bestbuy.com', port=443): Max retries exceeded with url: /site/speakers/floor-speakers/abcat0205003.c?id=abcat0205003&page=2 (Caused by SSLError(SSLCertVerificationError(1, '[SSL: CERTIFICATE_VERIFY_FAILED] certificate verify failed: self signed certificate (_ssl.c:997)')))
urllib3.connectionpool:DEBUG:2022-10-04 22:14:45,411:Starting new HTTPS connection (1): www.bestbuy.com:443
urllib3.connectionpool:DEBUG:2022-10-04 22:14:45,828:https://www.bestbuy.com:443 "GET /site/speakers/floor-speakers/abcat0205003.c?id=abcat0205003&page=2 HTTP/1.1" 200 1659
urllib3.connectionpool:DEBUG:2022-10-04 22:20:06,088:Starting new HTTPS connection (1): free-proxy-list.net:443
urllib3.connectionpool:DEBUG:2022-10-04 22:20:06,865:https://free-proxy-list.net:443 "GET / HTTP/1.1" 200 None
urllib3.connectionpool:DEBUG:2022-10-04 22:20:07,114:Starting new HTTPS connection (1): www.costco.com:443
urllib3.connectionpool:DEBUG:2022-10-04 22:39:09,868:Starting new HTTPS connection (1): free-proxy-list.net:443
urllib3.connectionpool:DEBUG:2022-10-04 22:39:10,723:https://free-proxy-list.net:443 "GET / HTTP/1.1" 200 None
urllib3.connectionpool:DEBUG:2022-10-04 22:39:10,963:Starting new HTTPS connection (1): www.costco.com:443
urllib3.connectionpool:DEBUG:2022-10-04 22:40:28,236:Starting new HTTPS connection (1): www.costco.com:443
urllib3.connectionpool:DEBUG:2022-10-04 22:40:29,137:https://www.costco.com:443 "GET /home-theater-systems.html HTTP/1.1" 200 None
urllib3.connectionpool:DEBUG:2022-10-04 22:40:39,124:Starting new HTTPS connection (1): www.costco.com:443
urllib3.connectionpool:DEBUG:2022-10-04 22:40:40,824:https://www.costco.com:443 "GET /home-theater-systems.html HTTP/1.1" 200 None
urllib3.connectionpool:DEBUG:2022-10-04 22:41:40,059:Starting new HTTPS connection (1): www.costco.com:443
urllib3.connectionpool:DEBUG:2022-10-04 22:41:41,728:https://www.costco.com:443 "GET /home-theater-systems.html HTTP/1.1" 200 None
urllib3.connectionpool:DEBUG:2022-10-04 22:42:23,556:Starting new HTTPS connection (1): www.costco.com:443
urllib3.connectionpool:DEBUG:2022-10-04 22:42:24,433:https://www.costco.com:443 "GET /home-theater-systems.html HTTP/1.1" 200 None
urllib3.connectionpool:DEBUG:2022-10-04 22:43:14,586:Starting new HTTPS connection (1): www.costco.com:443
urllib3.connectionpool:DEBUG:2022-10-04 22:43:15,348:https://www.costco.com:443 "GET /home-theater-systems.html HTTP/1.1" 200 None
urllib3.connectionpool:DEBUG:2022-10-04 22:49:42,919:Starting new HTTPS connection (1): www.costco.com:443
urllib3.connectionpool:DEBUG:2022-10-04 22:49:44,838:https://www.costco.com:443 "GET /klipsch-the-fives-speaker%2C-2-pack.product.100800459.html HTTP/1.1" 200 None
urllib3.connectionpool:DEBUG:2022-10-04 22:50:52,763:Starting new HTTPS connection (1): www.costco.com:443
urllib3.connectionpool:DEBUG:2022-10-04 22:50:53,466:https://www.costco.com:443 "GET /klipsch-the-fives-speaker%2C-2-pack.product.100800459.html HTTP/1.1" 200 None
urllib3.connectionpool:DEBUG:2022-10-04 22:51:16,036:Starting new HTTPS connection (1): www.costco.com:443
urllib3.connectionpool:DEBUG:2022-10-04 22:51:16,278:https://www.costco.com:443 "GET /klipsch-the-fives-speaker%2C-2-pack.product.100800459.html HTTP/1.1" 200 None
urllib3.connectionpool:DEBUG:2022-10-04 22:51:27,608:Starting new HTTPS connection (1): www.costco.com:443
urllib3.connectionpool:DEBUG:2022-10-04 22:51:27,721:https://www.costco.com:443 "GET /klipsch-the-fives-speaker%2C-2-pack.product.100800459.html HTTP/1.1" 200 None
urllib3.connectionpool:DEBUG:2022-10-04 22:53:07,480:Starting new HTTPS connection (1): www.costco.com:443
urllib3.connectionpool:DEBUG:2022-10-04 22:53:07,602:https://www.costco.com:443 "GET /klipsch-the-fives-speaker%2C-2-pack.product.100800459.html HTTP/1.1" 200 None
urllib3.connectionpool:DEBUG:2022-10-04 22:53:12,606:Starting new HTTPS connection (1): www.costco.com:443
urllib3.connectionpool:DEBUG:2022-10-04 22:53:12,715:https://www.costco.com:443 "GET /klipsch-the-fives-speaker%2C-2-pack.product.100800459.html HTTP/1.1" 200 None
urllib3.connectionpool:DEBUG:2022-10-04 23:27:51,369:Starting new HTTPS connection (1): free-proxy-list.net:443
urllib3.connectionpool:DEBUG:2022-10-04 23:27:52,091:https://free-proxy-list.net:443 "GET / HTTP/1.1" 200 None
urllib3.connectionpool:DEBUG:2022-10-04 23:27:52,240:Starting new HTTPS connection (1): www.newegg.com:443
urllib3.connectionpool:DEBUG:2022-10-04 23:28:43,626:Starting new HTTPS connection (1): free-proxy-list.net:443
urllib3.connectionpool:DEBUG:2022-10-04 23:28:44,123:https://free-proxy-list.net:443 "GET / HTTP/1.1" 200 None
urllib3.connectionpool:DEBUG:2022-10-04 23:28:44,274:Starting new HTTPS connection (1): www.newegg.com:443
root:ERROR:2022-10-04 23:28:54,005:HTTPSConnectionPool(host='www.newegg.com', port=443): Max retries exceeded with url: /klipsch-r-625fa-reference/p/12K-00EF-000N4 (Caused by SSLError(SSLCertVerificationError(1, '[SSL: CERTIFICATE_VERIFY_FAILED] certificate verify failed: self signed certificate in certificate chain (_ssl.c:997)')))
Traceback (most recent call last):
  File "C:\Users\DELL\anaconda3\envs\Products_scraper\lib\site-packages\urllib3\connectionpool.py", line 700, in urlopen
    self._prepare_proxy(conn)
  File "C:\Users\DELL\anaconda3\envs\Products_scraper\lib\site-packages\urllib3\connectionpool.py", line 996, in _prepare_proxy
    conn.connect()
  File "C:\Users\DELL\anaconda3\envs\Products_scraper\lib\site-packages\urllib3\connection.py", line 414, in connect
    self.sock = ssl_wrap_socket(
  File "C:\Users\DELL\anaconda3\envs\Products_scraper\lib\site-packages\urllib3\util\ssl_.py", line 449, in ssl_wrap_socket
    ssl_sock = _ssl_wrap_socket_impl(
  File "C:\Users\DELL\anaconda3\envs\Products_scraper\lib\site-packages\urllib3\util\ssl_.py", line 493, in _ssl_wrap_socket_impl
    return ssl_context.wrap_socket(sock, server_hostname=server_hostname)
  File "C:\Users\DELL\anaconda3\envs\Products_scraper\lib\ssl.py", line 512, in wrap_socket
    return self.sslsocket_class._create(
  File "C:\Users\DELL\anaconda3\envs\Products_scraper\lib\ssl.py", line 1070, in _create
    self.do_handshake()
  File "C:\Users\DELL\anaconda3\envs\Products_scraper\lib\ssl.py", line 1341, in do_handshake
    self._sslobj.do_handshake()
ssl.SSLCertVerificationError: [SSL: CERTIFICATE_VERIFY_FAILED] certificate verify failed: self signed certificate in certificate chain (_ssl.c:997)

During handling of the above exception, another exception occurred:

Traceback (most recent call last):
  File "C:\Users\DELL\anaconda3\envs\Products_scraper\lib\site-packages\requests\adapters.py", line 489, in send
    resp = conn.urlopen(
  File "C:\Users\DELL\anaconda3\envs\Products_scraper\lib\site-packages\urllib3\connectionpool.py", line 787, in urlopen
    retries = retries.increment(
  File "C:\Users\DELL\anaconda3\envs\Products_scraper\lib\site-packages\urllib3\util\retry.py", line 592, in increment
    raise MaxRetryError(_pool, url, error or ResponseError(cause))
urllib3.exceptions.MaxRetryError: HTTPSConnectionPool(host='www.newegg.com', port=443): Max retries exceeded with url: /klipsch-r-625fa-reference/p/12K-00EF-000N4 (Caused by SSLError(SSLCertVerificationError(1, '[SSL: CERTIFICATE_VERIFY_FAILED] certificate verify failed: self signed certificate in certificate chain (_ssl.c:997)')))

During handling of the above exception, another exception occurred:

Traceback (most recent call last):
  File "C:\Users\DELL\Desktop\Python work\Products_scraper\extractors\send_request.py", line 75, in send_request
    page = requests.get(url, headers=HEADERS, proxies=ip)
  File "C:\Users\DELL\anaconda3\envs\Products_scraper\lib\site-packages\requests\api.py", line 73, in get
    return request("get", url, params=params, **kwargs)
  File "C:\Users\DELL\anaconda3\envs\Products_scraper\lib\site-packages\requests\api.py", line 59, in request
    return session.request(method=method, url=url, **kwargs)
  File "C:\Users\DELL\anaconda3\envs\Products_scraper\lib\site-packages\requests\sessions.py", line 587, in request
    resp = self.send(prep, **send_kwargs)
  File "C:\Users\DELL\anaconda3\envs\Products_scraper\lib\site-packages\requests\sessions.py", line 701, in send
    r = adapter.send(request, **kwargs)
  File "C:\Users\DELL\anaconda3\envs\Products_scraper\lib\site-packages\requests\adapters.py", line 563, in send
    raise SSLError(e, request=request)
requests.exceptions.SSLError: HTTPSConnectionPool(host='www.newegg.com', port=443): Max retries exceeded with url: /klipsch-r-625fa-reference/p/12K-00EF-000N4 (Caused by SSLError(SSLCertVerificationError(1, '[SSL: CERTIFICATE_VERIFY_FAILED] certificate verify failed: self signed certificate in certificate chain (_ssl.c:997)')))
urllib3.connectionpool:DEBUG:2022-10-04 23:28:54,026:Starting new HTTPS connection (1): www.newegg.com:443
urllib3.connectionpool:DEBUG:2022-10-04 23:28:56,400:https://www.newegg.com:443 "GET /klipsch-r-625fa-reference/p/12K-00EF-000N4 HTTP/1.1" 200 35693
urllib3.connectionpool:DEBUG:2022-10-04 23:29:01,237:Starting new HTTPS connection (1): free-proxy-list.net:443
urllib3.connectionpool:DEBUG:2022-10-04 23:29:01,820:https://free-proxy-list.net:443 "GET / HTTP/1.1" 200 None
urllib3.connectionpool:DEBUG:2022-10-04 23:29:01,960:Starting new HTTPS connection (1): www.newegg.com:443
root:ERROR:2022-10-04 23:29:13,521:HTTPSConnectionPool(host='www.newegg.com', port=443): Max retries exceeded with url: /klipsch-r-625fa-reference/p/12K-00EF-000N4R (Caused by SSLError(SSLCertVerificationError(1, '[SSL: CERTIFICATE_VERIFY_FAILED] certificate verify failed: self signed certificate in certificate chain (_ssl.c:997)')))
Traceback (most recent call last):
  File "C:\Users\DELL\anaconda3\envs\Products_scraper\lib\site-packages\urllib3\connectionpool.py", line 700, in urlopen
    self._prepare_proxy(conn)
  File "C:\Users\DELL\anaconda3\envs\Products_scraper\lib\site-packages\urllib3\connectionpool.py", line 996, in _prepare_proxy
    conn.connect()
  File "C:\Users\DELL\anaconda3\envs\Products_scraper\lib\site-packages\urllib3\connection.py", line 414, in connect
    self.sock = ssl_wrap_socket(
  File "C:\Users\DELL\anaconda3\envs\Products_scraper\lib\site-packages\urllib3\util\ssl_.py", line 449, in ssl_wrap_socket
    ssl_sock = _ssl_wrap_socket_impl(
  File "C:\Users\DELL\anaconda3\envs\Products_scraper\lib\site-packages\urllib3\util\ssl_.py", line 493, in _ssl_wrap_socket_impl
    return ssl_context.wrap_socket(sock, server_hostname=server_hostname)
  File "C:\Users\DELL\anaconda3\envs\Products_scraper\lib\ssl.py", line 512, in wrap_socket
    return self.sslsocket_class._create(
  File "C:\Users\DELL\anaconda3\envs\Products_scraper\lib\ssl.py", line 1070, in _create
    self.do_handshake()
  File "C:\Users\DELL\anaconda3\envs\Products_scraper\lib\ssl.py", line 1341, in do_handshake
    self._sslobj.do_handshake()
ssl.SSLCertVerificationError: [SSL: CERTIFICATE_VERIFY_FAILED] certificate verify failed: self signed certificate in certificate chain (_ssl.c:997)

During handling of the above exception, another exception occurred:

Traceback (most recent call last):
  File "C:\Users\DELL\anaconda3\envs\Products_scraper\lib\site-packages\requests\adapters.py", line 489, in send
    resp = conn.urlopen(
  File "C:\Users\DELL\anaconda3\envs\Products_scraper\lib\site-packages\urllib3\connectionpool.py", line 787, in urlopen
    retries = retries.increment(
  File "C:\Users\DELL\anaconda3\envs\Products_scraper\lib\site-packages\urllib3\util\retry.py", line 592, in increment
    raise MaxRetryError(_pool, url, error or ResponseError(cause))
urllib3.exceptions.MaxRetryError: HTTPSConnectionPool(host='www.newegg.com', port=443): Max retries exceeded with url: /klipsch-r-625fa-reference/p/12K-00EF-000N4R (Caused by SSLError(SSLCertVerificationError(1, '[SSL: CERTIFICATE_VERIFY_FAILED] certificate verify failed: self signed certificate in certificate chain (_ssl.c:997)')))

During handling of the above exception, another exception occurred:

Traceback (most recent call last):
  File "C:\Users\DELL\Desktop\Python work\Products_scraper\extractors\send_request.py", line 75, in send_request
    page = requests.get(url, headers=HEADERS, proxies=ip)
  File "C:\Users\DELL\anaconda3\envs\Products_scraper\lib\site-packages\requests\api.py", line 73, in get
    return request("get", url, params=params, **kwargs)
  File "C:\Users\DELL\anaconda3\envs\Products_scraper\lib\site-packages\requests\api.py", line 59, in request
    return session.request(method=method, url=url, **kwargs)
  File "C:\Users\DELL\anaconda3\envs\Products_scraper\lib\site-packages\requests\sessions.py", line 587, in request
    resp = self.send(prep, **send_kwargs)
  File "C:\Users\DELL\anaconda3\envs\Products_scraper\lib\site-packages\requests\sessions.py", line 701, in send
    r = adapter.send(request, **kwargs)
  File "C:\Users\DELL\anaconda3\envs\Products_scraper\lib\site-packages\requests\adapters.py", line 563, in send
    raise SSLError(e, request=request)
requests.exceptions.SSLError: HTTPSConnectionPool(host='www.newegg.com', port=443): Max retries exceeded with url: /klipsch-r-625fa-reference/p/12K-00EF-000N4R (Caused by SSLError(SSLCertVerificationError(1, '[SSL: CERTIFICATE_VERIFY_FAILED] certificate verify failed: self signed certificate in certificate chain (_ssl.c:997)')))
urllib3.connectionpool:DEBUG:2022-10-04 23:29:13,524:Starting new HTTPS connection (1): www.newegg.com:443
root:ERROR:2022-10-04 23:29:14,144:HTTPSConnectionPool(host='www.newegg.com', port=443): Max retries exceeded with url: /klipsch-r-625fa-reference/p/12K-00EF-000N4R (Caused by ProxyError('Cannot connect to proxy.', ConnectionResetError(10054, 'An existing connection was forcibly closed by the remote host', None, 10054, None)))
Traceback (most recent call last):
  File "C:\Users\DELL\anaconda3\envs\Products_scraper\lib\site-packages\urllib3\connectionpool.py", line 700, in urlopen
    self._prepare_proxy(conn)
  File "C:\Users\DELL\anaconda3\envs\Products_scraper\lib\site-packages\urllib3\connectionpool.py", line 996, in _prepare_proxy
    conn.connect()
  File "C:\Users\DELL\anaconda3\envs\Products_scraper\lib\site-packages\urllib3\connection.py", line 369, in connect
    self._tunnel()
  File "C:\Users\DELL\anaconda3\envs\Products_scraper\lib\http\client.py", line 920, in _tunnel
    (version, code, message) = response._read_status()
  File "C:\Users\DELL\anaconda3\envs\Products_scraper\lib\http\client.py", line 279, in _read_status
    line = str(self.fp.readline(_MAXLINE + 1), "iso-8859-1")
  File "C:\Users\DELL\anaconda3\envs\Products_scraper\lib\socket.py", line 705, in readinto
    return self._sock.recv_into(b)
ConnectionResetError: [WinError 10054] An existing connection was forcibly closed by the remote host

During handling of the above exception, another exception occurred:

Traceback (most recent call last):
  File "C:\Users\DELL\anaconda3\envs\Products_scraper\lib\site-packages\requests\adapters.py", line 489, in send
    resp = conn.urlopen(
  File "C:\Users\DELL\anaconda3\envs\Products_scraper\lib\site-packages\urllib3\connectionpool.py", line 787, in urlopen
    retries = retries.increment(
  File "C:\Users\DELL\anaconda3\envs\Products_scraper\lib\site-packages\urllib3\util\retry.py", line 592, in increment
    raise MaxRetryError(_pool, url, error or ResponseError(cause))
urllib3.exceptions.MaxRetryError: HTTPSConnectionPool(host='www.newegg.com', port=443): Max retries exceeded with url: /klipsch-r-625fa-reference/p/12K-00EF-000N4R (Caused by ProxyError('Cannot connect to proxy.', ConnectionResetError(10054, 'An existing connection was forcibly closed by the remote host', None, 10054, None)))

During handling of the above exception, another exception occurred:

Traceback (most recent call last):
  File "C:\Users\DELL\Desktop\Python work\Products_scraper\extractors\send_request.py", line 75, in send_request
    page = requests.get(url, headers=HEADERS, proxies=ip)
  File "C:\Users\DELL\anaconda3\envs\Products_scraper\lib\site-packages\requests\api.py", line 73, in get
    return request("get", url, params=params, **kwargs)
  File "C:\Users\DELL\anaconda3\envs\Products_scraper\lib\site-packages\requests\api.py", line 59, in request
    return session.request(method=method, url=url, **kwargs)
  File "C:\Users\DELL\anaconda3\envs\Products_scraper\lib\site-packages\requests\sessions.py", line 587, in request
    resp = self.send(prep, **send_kwargs)
  File "C:\Users\DELL\anaconda3\envs\Products_scraper\lib\site-packages\requests\sessions.py", line 701, in send
    r = adapter.send(request, **kwargs)
  File "C:\Users\DELL\anaconda3\envs\Products_scraper\lib\site-packages\requests\adapters.py", line 559, in send
    raise ProxyError(e, request=request)
requests.exceptions.ProxyError: HTTPSConnectionPool(host='www.newegg.com', port=443): Max retries exceeded with url: /klipsch-r-625fa-reference/p/12K-00EF-000N4R (Caused by ProxyError('Cannot connect to proxy.', ConnectionResetError(10054, 'An existing connection was forcibly closed by the remote host', None, 10054, None)))
urllib3.connectionpool:DEBUG:2022-10-04 23:29:14,164:Starting new HTTPS connection (1): www.newegg.com:443
urllib3.connectionpool:DEBUG:2022-10-04 23:29:16,114:https://www.newegg.com:443 "GET /klipsch-r-625fa-reference/p/12K-00EF-000N4R HTTP/1.1" 200 22105
urllib3.connectionpool:DEBUG:2022-10-04 23:29:20,490:Starting new HTTPS connection (1): free-proxy-list.net:443
urllib3.connectionpool:DEBUG:2022-10-04 23:29:20,968:https://free-proxy-list.net:443 "GET / HTTP/1.1" 200 None
urllib3.connectionpool:DEBUG:2022-10-04 23:29:21,111:Starting new HTTPS connection (1): www.newegg.com:443
root:ERROR:2022-10-04 23:29:43,197:HTTPSConnectionPool(host='www.newegg.com', port=443): Max retries exceeded with url: /klipsch-1062295/p/0S6-0033-001N6 (Caused by SSLError(SSLCertVerificationError(1, '[SSL: CERTIFICATE_VERIFY_FAILED] certificate verify failed: self signed certificate in certificate chain (_ssl.c:997)')))
Traceback (most recent call last):
  File "C:\Users\DELL\anaconda3\envs\Products_scraper\lib\site-packages\urllib3\connectionpool.py", line 700, in urlopen
    self._prepare_proxy(conn)
  File "C:\Users\DELL\anaconda3\envs\Products_scraper\lib\site-packages\urllib3\connectionpool.py", line 996, in _prepare_proxy
    conn.connect()
  File "C:\Users\DELL\anaconda3\envs\Products_scraper\lib\site-packages\urllib3\connection.py", line 414, in connect
    self.sock = ssl_wrap_socket(
  File "C:\Users\DELL\anaconda3\envs\Products_scraper\lib\site-packages\urllib3\util\ssl_.py", line 449, in ssl_wrap_socket
    ssl_sock = _ssl_wrap_socket_impl(
  File "C:\Users\DELL\anaconda3\envs\Products_scraper\lib\site-packages\urllib3\util\ssl_.py", line 493, in _ssl_wrap_socket_impl
    return ssl_context.wrap_socket(sock, server_hostname=server_hostname)
  File "C:\Users\DELL\anaconda3\envs\Products_scraper\lib\ssl.py", line 512, in wrap_socket
    return self.sslsocket_class._create(
  File "C:\Users\DELL\anaconda3\envs\Products_scraper\lib\ssl.py", line 1070, in _create
    self.do_handshake()
  File "C:\Users\DELL\anaconda3\envs\Products_scraper\lib\ssl.py", line 1341, in do_handshake
    self._sslobj.do_handshake()
ssl.SSLCertVerificationError: [SSL: CERTIFICATE_VERIFY_FAILED] certificate verify failed: self signed certificate in certificate chain (_ssl.c:997)

During handling of the above exception, another exception occurred:

Traceback (most recent call last):
  File "C:\Users\DELL\anaconda3\envs\Products_scraper\lib\site-packages\requests\adapters.py", line 489, in send
    resp = conn.urlopen(
  File "C:\Users\DELL\anaconda3\envs\Products_scraper\lib\site-packages\urllib3\connectionpool.py", line 787, in urlopen
    retries = retries.increment(
  File "C:\Users\DELL\anaconda3\envs\Products_scraper\lib\site-packages\urllib3\util\retry.py", line 592, in increment
    raise MaxRetryError(_pool, url, error or ResponseError(cause))
urllib3.exceptions.MaxRetryError: HTTPSConnectionPool(host='www.newegg.com', port=443): Max retries exceeded with url: /klipsch-1062295/p/0S6-0033-001N6 (Caused by SSLError(SSLCertVerificationError(1, '[SSL: CERTIFICATE_VERIFY_FAILED] certificate verify failed: self signed certificate in certificate chain (_ssl.c:997)')))

During handling of the above exception, another exception occurred:

Traceback (most recent call last):
  File "C:\Users\DELL\Desktop\Python work\Products_scraper\extractors\send_request.py", line 75, in send_request
    page = requests.get(url, headers=HEADERS, proxies=ip)
  File "C:\Users\DELL\anaconda3\envs\Products_scraper\lib\site-packages\requests\api.py", line 73, in get
    return request("get", url, params=params, **kwargs)
  File "C:\Users\DELL\anaconda3\envs\Products_scraper\lib\site-packages\requests\api.py", line 59, in request
    return session.request(method=method, url=url, **kwargs)
  File "C:\Users\DELL\anaconda3\envs\Products_scraper\lib\site-packages\requests\sessions.py", line 587, in request
    resp = self.send(prep, **send_kwargs)
  File "C:\Users\DELL\anaconda3\envs\Products_scraper\lib\site-packages\requests\sessions.py", line 701, in send
    r = adapter.send(request, **kwargs)
  File "C:\Users\DELL\anaconda3\envs\Products_scraper\lib\site-packages\requests\adapters.py", line 563, in send
    raise SSLError(e, request=request)
requests.exceptions.SSLError: HTTPSConnectionPool(host='www.newegg.com', port=443): Max retries exceeded with url: /klipsch-1062295/p/0S6-0033-001N6 (Caused by SSLError(SSLCertVerificationError(1, '[SSL: CERTIFICATE_VERIFY_FAILED] certificate verify failed: self signed certificate in certificate chain (_ssl.c:997)')))
urllib3.connectionpool:DEBUG:2022-10-04 23:29:43,201:Starting new HTTPS connection (1): www.newegg.com:443
urllib3.connectionpool:DEBUG:2022-10-04 23:29:45,161:https://www.newegg.com:443 "GET /klipsch-1062295/p/0S6-0033-001N6 HTTP/1.1" 200 26212
urllib3.connectionpool:DEBUG:2022-10-04 23:29:50,030:Starting new HTTPS connection (1): free-proxy-list.net:443
urllib3.connectionpool:DEBUG:2022-10-04 23:29:50,514:https://free-proxy-list.net:443 "GET / HTTP/1.1" 200 None
urllib3.connectionpool:DEBUG:2022-10-04 23:29:50,726:Starting new HTTPS connection (1): www.newegg.com:443
root:ERROR:2022-10-04 23:30:06,213:HTTPSConnectionPool(host='www.newegg.com', port=443): Max retries exceeded with url: /p/0S6-001N-00069 (Caused by SSLError(SSLCertVerificationError(1, '[SSL: CERTIFICATE_VERIFY_FAILED] certificate verify failed: self signed certificate in certificate chain (_ssl.c:997)')))
Traceback (most recent call last):
  File "C:\Users\DELL\anaconda3\envs\Products_scraper\lib\site-packages\urllib3\connectionpool.py", line 700, in urlopen
    self._prepare_proxy(conn)
  File "C:\Users\DELL\anaconda3\envs\Products_scraper\lib\site-packages\urllib3\connectionpool.py", line 996, in _prepare_proxy
    conn.connect()
  File "C:\Users\DELL\anaconda3\envs\Products_scraper\lib\site-packages\urllib3\connection.py", line 414, in connect
    self.sock = ssl_wrap_socket(
  File "C:\Users\DELL\anaconda3\envs\Products_scraper\lib\site-packages\urllib3\util\ssl_.py", line 449, in ssl_wrap_socket
    ssl_sock = _ssl_wrap_socket_impl(
  File "C:\Users\DELL\anaconda3\envs\Products_scraper\lib\site-packages\urllib3\util\ssl_.py", line 493, in _ssl_wrap_socket_impl
    return ssl_context.wrap_socket(sock, server_hostname=server_hostname)
  File "C:\Users\DELL\anaconda3\envs\Products_scraper\lib\ssl.py", line 512, in wrap_socket
    return self.sslsocket_class._create(
  File "C:\Users\DELL\anaconda3\envs\Products_scraper\lib\ssl.py", line 1070, in _create
    self.do_handshake()
  File "C:\Users\DELL\anaconda3\envs\Products_scraper\lib\ssl.py", line 1341, in do_handshake
    self._sslobj.do_handshake()
ssl.SSLCertVerificationError: [SSL: CERTIFICATE_VERIFY_FAILED] certificate verify failed: self signed certificate in certificate chain (_ssl.c:997)

During handling of the above exception, another exception occurred:

Traceback (most recent call last):
  File "C:\Users\DELL\anaconda3\envs\Products_scraper\lib\site-packages\requests\adapters.py", line 489, in send
    resp = conn.urlopen(
  File "C:\Users\DELL\anaconda3\envs\Products_scraper\lib\site-packages\urllib3\connectionpool.py", line 787, in urlopen
    retries = retries.increment(
  File "C:\Users\DELL\anaconda3\envs\Products_scraper\lib\site-packages\urllib3\util\retry.py", line 592, in increment
    raise MaxRetryError(_pool, url, error or ResponseError(cause))
urllib3.exceptions.MaxRetryError: HTTPSConnectionPool(host='www.newegg.com', port=443): Max retries exceeded with url: /p/0S6-001N-00069 (Caused by SSLError(SSLCertVerificationError(1, '[SSL: CERTIFICATE_VERIFY_FAILED] certificate verify failed: self signed certificate in certificate chain (_ssl.c:997)')))

During handling of the above exception, another exception occurred:

Traceback (most recent call last):
  File "C:\Users\DELL\Desktop\Python work\Products_scraper\extractors\send_request.py", line 75, in send_request
    page = requests.get(url, headers=HEADERS, proxies=ip)
  File "C:\Users\DELL\anaconda3\envs\Products_scraper\lib\site-packages\requests\api.py", line 73, in get
    return request("get", url, params=params, **kwargs)
  File "C:\Users\DELL\anaconda3\envs\Products_scraper\lib\site-packages\requests\api.py", line 59, in request
    return session.request(method=method, url=url, **kwargs)
  File "C:\Users\DELL\anaconda3\envs\Products_scraper\lib\site-packages\requests\sessions.py", line 587, in request
    resp = self.send(prep, **send_kwargs)
  File "C:\Users\DELL\anaconda3\envs\Products_scraper\lib\site-packages\requests\sessions.py", line 701, in send
    r = adapter.send(request, **kwargs)
  File "C:\Users\DELL\anaconda3\envs\Products_scraper\lib\site-packages\requests\adapters.py", line 563, in send
    raise SSLError(e, request=request)
requests.exceptions.SSLError: HTTPSConnectionPool(host='www.newegg.com', port=443): Max retries exceeded with url: /p/0S6-001N-00069 (Caused by SSLError(SSLCertVerificationError(1, '[SSL: CERTIFICATE_VERIFY_FAILED] certificate verify failed: self signed certificate in certificate chain (_ssl.c:997)')))
urllib3.connectionpool:DEBUG:2022-10-04 23:30:06,217:Starting new HTTPS connection (1): www.newegg.com:443
root:ERROR:2022-10-04 23:30:06,566:HTTPSConnectionPool(host='www.newegg.com', port=443): Max retries exceeded with url: /p/0S6-001N-00069 (Caused by ProxyError('Cannot connect to proxy.', ConnectionResetError(10054, 'An existing connection was forcibly closed by the remote host', None, 10054, None)))
Traceback (most recent call last):
  File "C:\Users\DELL\anaconda3\envs\Products_scraper\lib\site-packages\urllib3\connectionpool.py", line 700, in urlopen
    self._prepare_proxy(conn)
  File "C:\Users\DELL\anaconda3\envs\Products_scraper\lib\site-packages\urllib3\connectionpool.py", line 996, in _prepare_proxy
    conn.connect()
  File "C:\Users\DELL\anaconda3\envs\Products_scraper\lib\site-packages\urllib3\connection.py", line 369, in connect
    self._tunnel()
  File "C:\Users\DELL\anaconda3\envs\Products_scraper\lib\http\client.py", line 920, in _tunnel
    (version, code, message) = response._read_status()
  File "C:\Users\DELL\anaconda3\envs\Products_scraper\lib\http\client.py", line 279, in _read_status
    line = str(self.fp.readline(_MAXLINE + 1), "iso-8859-1")
  File "C:\Users\DELL\anaconda3\envs\Products_scraper\lib\socket.py", line 705, in readinto
    return self._sock.recv_into(b)
ConnectionResetError: [WinError 10054] An existing connection was forcibly closed by the remote host

During handling of the above exception, another exception occurred:

Traceback (most recent call last):
  File "C:\Users\DELL\anaconda3\envs\Products_scraper\lib\site-packages\requests\adapters.py", line 489, in send
    resp = conn.urlopen(
  File "C:\Users\DELL\anaconda3\envs\Products_scraper\lib\site-packages\urllib3\connectionpool.py", line 787, in urlopen
    retries = retries.increment(
  File "C:\Users\DELL\anaconda3\envs\Products_scraper\lib\site-packages\urllib3\util\retry.py", line 592, in increment
    raise MaxRetryError(_pool, url, error or ResponseError(cause))
urllib3.exceptions.MaxRetryError: HTTPSConnectionPool(host='www.newegg.com', port=443): Max retries exceeded with url: /p/0S6-001N-00069 (Caused by ProxyError('Cannot connect to proxy.', ConnectionResetError(10054, 'An existing connection was forcibly closed by the remote host', None, 10054, None)))

During handling of the above exception, another exception occurred:

Traceback (most recent call last):
  File "C:\Users\DELL\Desktop\Python work\Products_scraper\extractors\send_request.py", line 75, in send_request
    page = requests.get(url, headers=HEADERS, proxies=ip)
  File "C:\Users\DELL\anaconda3\envs\Products_scraper\lib\site-packages\requests\api.py", line 73, in get
    return request("get", url, params=params, **kwargs)
  File "C:\Users\DELL\anaconda3\envs\Products_scraper\lib\site-packages\requests\api.py", line 59, in request
    return session.request(method=method, url=url, **kwargs)
  File "C:\Users\DELL\anaconda3\envs\Products_scraper\lib\site-packages\requests\sessions.py", line 587, in request
    resp = self.send(prep, **send_kwargs)
  File "C:\Users\DELL\anaconda3\envs\Products_scraper\lib\site-packages\requests\sessions.py", line 701, in send
    r = adapter.send(request, **kwargs)
  File "C:\Users\DELL\anaconda3\envs\Products_scraper\lib\site-packages\requests\adapters.py", line 559, in send
    raise ProxyError(e, request=request)
requests.exceptions.ProxyError: HTTPSConnectionPool(host='www.newegg.com', port=443): Max retries exceeded with url: /p/0S6-001N-00069 (Caused by ProxyError('Cannot connect to proxy.', ConnectionResetError(10054, 'An existing connection was forcibly closed by the remote host', None, 10054, None)))
urllib3.connectionpool:DEBUG:2022-10-04 23:30:06,569:Starting new HTTPS connection (1): www.newegg.com:443
urllib3.connectionpool:DEBUG:2022-10-04 23:30:07,462:https://www.newegg.com:443 "GET /p/0S6-001N-00069 HTTP/1.1" 200 27832
urllib3.connectionpool:DEBUG:2022-10-04 23:30:11,954:Starting new HTTPS connection (1): free-proxy-list.net:443
urllib3.connectionpool:DEBUG:2022-10-04 23:30:12,510:https://free-proxy-list.net:443 "GET / HTTP/1.1" 200 None
urllib3.connectionpool:DEBUG:2022-10-04 23:30:12,954:Starting new HTTPS connection (1): www.newegg.com:443
root:ERROR:2022-10-04 23:30:31,241:HTTPSConnectionPool(host='www.newegg.com', port=443): Max retries exceeded with url: /p/0S6-00SH-00143 (Caused by SSLError(SSLCertVerificationError(1, '[SSL: CERTIFICATE_VERIFY_FAILED] certificate verify failed: self signed certificate in certificate chain (_ssl.c:997)')))
Traceback (most recent call last):
  File "C:\Users\DELL\anaconda3\envs\Products_scraper\lib\site-packages\urllib3\connectionpool.py", line 700, in urlopen
    self._prepare_proxy(conn)
  File "C:\Users\DELL\anaconda3\envs\Products_scraper\lib\site-packages\urllib3\connectionpool.py", line 996, in _prepare_proxy
    conn.connect()
  File "C:\Users\DELL\anaconda3\envs\Products_scraper\lib\site-packages\urllib3\connection.py", line 414, in connect
    self.sock = ssl_wrap_socket(
  File "C:\Users\DELL\anaconda3\envs\Products_scraper\lib\site-packages\urllib3\util\ssl_.py", line 449, in ssl_wrap_socket
    ssl_sock = _ssl_wrap_socket_impl(
  File "C:\Users\DELL\anaconda3\envs\Products_scraper\lib\site-packages\urllib3\util\ssl_.py", line 493, in _ssl_wrap_socket_impl
    return ssl_context.wrap_socket(sock, server_hostname=server_hostname)
  File "C:\Users\DELL\anaconda3\envs\Products_scraper\lib\ssl.py", line 512, in wrap_socket
    return self.sslsocket_class._create(
  File "C:\Users\DELL\anaconda3\envs\Products_scraper\lib\ssl.py", line 1070, in _create
    self.do_handshake()
  File "C:\Users\DELL\anaconda3\envs\Products_scraper\lib\ssl.py", line 1341, in do_handshake
    self._sslobj.do_handshake()
ssl.SSLCertVerificationError: [SSL: CERTIFICATE_VERIFY_FAILED] certificate verify failed: self signed certificate in certificate chain (_ssl.c:997)

During handling of the above exception, another exception occurred:

Traceback (most recent call last):
  File "C:\Users\DELL\anaconda3\envs\Products_scraper\lib\site-packages\requests\adapters.py", line 489, in send
    resp = conn.urlopen(
  File "C:\Users\DELL\anaconda3\envs\Products_scraper\lib\site-packages\urllib3\connectionpool.py", line 787, in urlopen
    retries = retries.increment(
  File "C:\Users\DELL\anaconda3\envs\Products_scraper\lib\site-packages\urllib3\util\retry.py", line 592, in increment
    raise MaxRetryError(_pool, url, error or ResponseError(cause))
urllib3.exceptions.MaxRetryError: HTTPSConnectionPool(host='www.newegg.com', port=443): Max retries exceeded with url: /p/0S6-00SH-00143 (Caused by SSLError(SSLCertVerificationError(1, '[SSL: CERTIFICATE_VERIFY_FAILED] certificate verify failed: self signed certificate in certificate chain (_ssl.c:997)')))

During handling of the above exception, another exception occurred:

Traceback (most recent call last):
  File "C:\Users\DELL\Desktop\Python work\Products_scraper\extractors\send_request.py", line 75, in send_request
    page = requests.get(url, headers=HEADERS, proxies=ip)
  File "C:\Users\DELL\anaconda3\envs\Products_scraper\lib\site-packages\requests\api.py", line 73, in get
    return request("get", url, params=params, **kwargs)
  File "C:\Users\DELL\anaconda3\envs\Products_scraper\lib\site-packages\requests\api.py", line 59, in request
    return session.request(method=method, url=url, **kwargs)
  File "C:\Users\DELL\anaconda3\envs\Products_scraper\lib\site-packages\requests\sessions.py", line 587, in request
    resp = self.send(prep, **send_kwargs)
  File "C:\Users\DELL\anaconda3\envs\Products_scraper\lib\site-packages\requests\sessions.py", line 701, in send
    r = adapter.send(request, **kwargs)
  File "C:\Users\DELL\anaconda3\envs\Products_scraper\lib\site-packages\requests\adapters.py", line 563, in send
    raise SSLError(e, request=request)
requests.exceptions.SSLError: HTTPSConnectionPool(host='www.newegg.com', port=443): Max retries exceeded with url: /p/0S6-00SH-00143 (Caused by SSLError(SSLCertVerificationError(1, '[SSL: CERTIFICATE_VERIFY_FAILED] certificate verify failed: self signed certificate in certificate chain (_ssl.c:997)')))
urllib3.connectionpool:DEBUG:2022-10-04 23:30:31,245:Starting new HTTPS connection (1): www.newegg.com:443
root:ERROR:2022-10-04 23:30:32,990:HTTPSConnectionPool(host='www.newegg.com', port=443): Max retries exceeded with url: /p/0S6-00SH-00143 (Caused by ProxyError('Cannot connect to proxy.', ConnectionResetError(10054, 'An existing connection was forcibly closed by the remote host', None, 10054, None)))
Traceback (most recent call last):
  File "C:\Users\DELL\anaconda3\envs\Products_scraper\lib\site-packages\urllib3\connectionpool.py", line 700, in urlopen
    self._prepare_proxy(conn)
  File "C:\Users\DELL\anaconda3\envs\Products_scraper\lib\site-packages\urllib3\connectionpool.py", line 996, in _prepare_proxy
    conn.connect()
  File "C:\Users\DELL\anaconda3\envs\Products_scraper\lib\site-packages\urllib3\connection.py", line 369, in connect
    self._tunnel()
  File "C:\Users\DELL\anaconda3\envs\Products_scraper\lib\http\client.py", line 920, in _tunnel
    (version, code, message) = response._read_status()
  File "C:\Users\DELL\anaconda3\envs\Products_scraper\lib\http\client.py", line 279, in _read_status
    line = str(self.fp.readline(_MAXLINE + 1), "iso-8859-1")
  File "C:\Users\DELL\anaconda3\envs\Products_scraper\lib\socket.py", line 705, in readinto
    return self._sock.recv_into(b)
ConnectionResetError: [WinError 10054] An existing connection was forcibly closed by the remote host

During handling of the above exception, another exception occurred:

Traceback (most recent call last):
  File "C:\Users\DELL\anaconda3\envs\Products_scraper\lib\site-packages\requests\adapters.py", line 489, in send
    resp = conn.urlopen(
  File "C:\Users\DELL\anaconda3\envs\Products_scraper\lib\site-packages\urllib3\connectionpool.py", line 787, in urlopen
    retries = retries.increment(
  File "C:\Users\DELL\anaconda3\envs\Products_scraper\lib\site-packages\urllib3\util\retry.py", line 592, in increment
    raise MaxRetryError(_pool, url, error or ResponseError(cause))
urllib3.exceptions.MaxRetryError: HTTPSConnectionPool(host='www.newegg.com', port=443): Max retries exceeded with url: /p/0S6-00SH-00143 (Caused by ProxyError('Cannot connect to proxy.', ConnectionResetError(10054, 'An existing connection was forcibly closed by the remote host', None, 10054, None)))

During handling of the above exception, another exception occurred:

Traceback (most recent call last):
  File "C:\Users\DELL\Desktop\Python work\Products_scraper\extractors\send_request.py", line 75, in send_request
    page = requests.get(url, headers=HEADERS, proxies=ip)
  File "C:\Users\DELL\anaconda3\envs\Products_scraper\lib\site-packages\requests\api.py", line 73, in get
    return request("get", url, params=params, **kwargs)
  File "C:\Users\DELL\anaconda3\envs\Products_scraper\lib\site-packages\requests\api.py", line 59, in request
    return session.request(method=method, url=url, **kwargs)
  File "C:\Users\DELL\anaconda3\envs\Products_scraper\lib\site-packages\requests\sessions.py", line 587, in request
    resp = self.send(prep, **send_kwargs)
  File "C:\Users\DELL\anaconda3\envs\Products_scraper\lib\site-packages\requests\sessions.py", line 701, in send
    r = adapter.send(request, **kwargs)
  File "C:\Users\DELL\anaconda3\envs\Products_scraper\lib\site-packages\requests\adapters.py", line 559, in send
    raise ProxyError(e, request=request)
requests.exceptions.ProxyError: HTTPSConnectionPool(host='www.newegg.com', port=443): Max retries exceeded with url: /p/0S6-00SH-00143 (Caused by ProxyError('Cannot connect to proxy.', ConnectionResetError(10054, 'An existing connection was forcibly closed by the remote host', None, 10054, None)))
urllib3.connectionpool:DEBUG:2022-10-04 23:30:32,993:Starting new HTTPS connection (1): www.newegg.com:443
urllib3.connectionpool:DEBUG:2022-10-04 23:30:33,699:https://www.newegg.com:443 "GET /p/0S6-00SH-00143 HTTP/1.1" 200 24829
urllib3.connectionpool:DEBUG:2022-10-04 23:30:38,415:Starting new HTTPS connection (1): free-proxy-list.net:443
urllib3.connectionpool:DEBUG:2022-10-04 23:30:38,987:https://free-proxy-list.net:443 "GET / HTTP/1.1" 200 None
urllib3.connectionpool:DEBUG:2022-10-04 23:30:39,186:Starting new HTTPS connection (1): www.newegg.com:443
root:ERROR:2022-10-04 23:30:52,725:HTTPSConnectionPool(host='www.newegg.com', port=443): Max retries exceeded with url: /klipsch-r-625fa-reference/p/12K-00EF-000N4 (Caused by SSLError(SSLCertVerificationError(1, '[SSL: CERTIFICATE_VERIFY_FAILED] certificate verify failed: self signed certificate in certificate chain (_ssl.c:997)')))
Traceback (most recent call last):
  File "C:\Users\DELL\anaconda3\envs\Products_scraper\lib\site-packages\urllib3\connectionpool.py", line 700, in urlopen
    self._prepare_proxy(conn)
  File "C:\Users\DELL\anaconda3\envs\Products_scraper\lib\site-packages\urllib3\connectionpool.py", line 996, in _prepare_proxy
    conn.connect()
  File "C:\Users\DELL\anaconda3\envs\Products_scraper\lib\site-packages\urllib3\connection.py", line 414, in connect
    self.sock = ssl_wrap_socket(
  File "C:\Users\DELL\anaconda3\envs\Products_scraper\lib\site-packages\urllib3\util\ssl_.py", line 449, in ssl_wrap_socket
    ssl_sock = _ssl_wrap_socket_impl(
  File "C:\Users\DELL\anaconda3\envs\Products_scraper\lib\site-packages\urllib3\util\ssl_.py", line 493, in _ssl_wrap_socket_impl
    return ssl_context.wrap_socket(sock, server_hostname=server_hostname)
  File "C:\Users\DELL\anaconda3\envs\Products_scraper\lib\ssl.py", line 512, in wrap_socket
    return self.sslsocket_class._create(
  File "C:\Users\DELL\anaconda3\envs\Products_scraper\lib\ssl.py", line 1070, in _create
    self.do_handshake()
  File "C:\Users\DELL\anaconda3\envs\Products_scraper\lib\ssl.py", line 1341, in do_handshake
    self._sslobj.do_handshake()
ssl.SSLCertVerificationError: [SSL: CERTIFICATE_VERIFY_FAILED] certificate verify failed: self signed certificate in certificate chain (_ssl.c:997)

During handling of the above exception, another exception occurred:

Traceback (most recent call last):
  File "C:\Users\DELL\anaconda3\envs\Products_scraper\lib\site-packages\requests\adapters.py", line 489, in send
    resp = conn.urlopen(
  File "C:\Users\DELL\anaconda3\envs\Products_scraper\lib\site-packages\urllib3\connectionpool.py", line 787, in urlopen
    retries = retries.increment(
  File "C:\Users\DELL\anaconda3\envs\Products_scraper\lib\site-packages\urllib3\util\retry.py", line 592, in increment
    raise MaxRetryError(_pool, url, error or ResponseError(cause))
urllib3.exceptions.MaxRetryError: HTTPSConnectionPool(host='www.newegg.com', port=443): Max retries exceeded with url: /klipsch-r-625fa-reference/p/12K-00EF-000N4 (Caused by SSLError(SSLCertVerificationError(1, '[SSL: CERTIFICATE_VERIFY_FAILED] certificate verify failed: self signed certificate in certificate chain (_ssl.c:997)')))

During handling of the above exception, another exception occurred:

Traceback (most recent call last):
  File "C:\Users\DELL\Desktop\Python work\Products_scraper\extractors\send_request.py", line 75, in send_request
    page = requests.get(url, headers=HEADERS, proxies=ip)
  File "C:\Users\DELL\anaconda3\envs\Products_scraper\lib\site-packages\requests\api.py", line 73, in get
    return request("get", url, params=params, **kwargs)
  File "C:\Users\DELL\anaconda3\envs\Products_scraper\lib\site-packages\requests\api.py", line 59, in request
    return session.request(method=method, url=url, **kwargs)
  File "C:\Users\DELL\anaconda3\envs\Products_scraper\lib\site-packages\requests\sessions.py", line 587, in request
    resp = self.send(prep, **send_kwargs)
  File "C:\Users\DELL\anaconda3\envs\Products_scraper\lib\site-packages\requests\sessions.py", line 701, in send
    r = adapter.send(request, **kwargs)
  File "C:\Users\DELL\anaconda3\envs\Products_scraper\lib\site-packages\requests\adapters.py", line 563, in send
    raise SSLError(e, request=request)
requests.exceptions.SSLError: HTTPSConnectionPool(host='www.newegg.com', port=443): Max retries exceeded with url: /klipsch-r-625fa-reference/p/12K-00EF-000N4 (Caused by SSLError(SSLCertVerificationError(1, '[SSL: CERTIFICATE_VERIFY_FAILED] certificate verify failed: self signed certificate in certificate chain (_ssl.c:997)')))
urllib3.connectionpool:DEBUG:2022-10-04 23:30:52,729:Starting new HTTPS connection (1): www.newegg.com:443
root:ERROR:2022-10-04 23:31:08,346:HTTPSConnectionPool(host='www.newegg.com', port=443): Max retries exceeded with url: /klipsch-r-625fa-reference/p/12K-00EF-000N4 (Caused by ProxyError('Cannot connect to proxy.', ConnectionResetError(10054, 'An existing connection was forcibly closed by the remote host', None, 10054, None)))
Traceback (most recent call last):
  File "C:\Users\DELL\anaconda3\envs\Products_scraper\lib\site-packages\urllib3\connectionpool.py", line 700, in urlopen
    self._prepare_proxy(conn)
  File "C:\Users\DELL\anaconda3\envs\Products_scraper\lib\site-packages\urllib3\connectionpool.py", line 996, in _prepare_proxy
    conn.connect()
  File "C:\Users\DELL\anaconda3\envs\Products_scraper\lib\site-packages\urllib3\connection.py", line 369, in connect
    self._tunnel()
  File "C:\Users\DELL\anaconda3\envs\Products_scraper\lib\http\client.py", line 920, in _tunnel
    (version, code, message) = response._read_status()
  File "C:\Users\DELL\anaconda3\envs\Products_scraper\lib\http\client.py", line 279, in _read_status
    line = str(self.fp.readline(_MAXLINE + 1), "iso-8859-1")
  File "C:\Users\DELL\anaconda3\envs\Products_scraper\lib\socket.py", line 705, in readinto
    return self._sock.recv_into(b)
ConnectionResetError: [WinError 10054] An existing connection was forcibly closed by the remote host

During handling of the above exception, another exception occurred:

Traceback (most recent call last):
  File "C:\Users\DELL\anaconda3\envs\Products_scraper\lib\site-packages\requests\adapters.py", line 489, in send
    resp = conn.urlopen(
  File "C:\Users\DELL\anaconda3\envs\Products_scraper\lib\site-packages\urllib3\connectionpool.py", line 787, in urlopen
    retries = retries.increment(
  File "C:\Users\DELL\anaconda3\envs\Products_scraper\lib\site-packages\urllib3\util\retry.py", line 592, in increment
    raise MaxRetryError(_pool, url, error or ResponseError(cause))
urllib3.exceptions.MaxRetryError: HTTPSConnectionPool(host='www.newegg.com', port=443): Max retries exceeded with url: /klipsch-r-625fa-reference/p/12K-00EF-000N4 (Caused by ProxyError('Cannot connect to proxy.', ConnectionResetError(10054, 'An existing connection was forcibly closed by the remote host', None, 10054, None)))

During handling of the above exception, another exception occurred:

Traceback (most recent call last):
  File "C:\Users\DELL\Desktop\Python work\Products_scraper\extractors\send_request.py", line 75, in send_request
    page = requests.get(url, headers=HEADERS, proxies=ip)
  File "C:\Users\DELL\anaconda3\envs\Products_scraper\lib\site-packages\requests\api.py", line 73, in get
    return request("get", url, params=params, **kwargs)
  File "C:\Users\DELL\anaconda3\envs\Products_scraper\lib\site-packages\requests\api.py", line 59, in request
    return session.request(method=method, url=url, **kwargs)
  File "C:\Users\DELL\anaconda3\envs\Products_scraper\lib\site-packages\requests\sessions.py", line 587, in request
    resp = self.send(prep, **send_kwargs)
  File "C:\Users\DELL\anaconda3\envs\Products_scraper\lib\site-packages\requests\sessions.py", line 701, in send
    r = adapter.send(request, **kwargs)
  File "C:\Users\DELL\anaconda3\envs\Products_scraper\lib\site-packages\requests\adapters.py", line 559, in send
    raise ProxyError(e, request=request)
requests.exceptions.ProxyError: HTTPSConnectionPool(host='www.newegg.com', port=443): Max retries exceeded with url: /klipsch-r-625fa-reference/p/12K-00EF-000N4 (Caused by ProxyError('Cannot connect to proxy.', ConnectionResetError(10054, 'An existing connection was forcibly closed by the remote host', None, 10054, None)))
urllib3.connectionpool:DEBUG:2022-10-04 23:31:08,349:Starting new HTTPS connection (1): www.newegg.com:443
urllib3.connectionpool:DEBUG:2022-10-04 23:31:09,022:https://www.newegg.com:443 "GET /klipsch-r-625fa-reference/p/12K-00EF-000N4 HTTP/1.1" 200 37164
urllib3.connectionpool:DEBUG:2022-10-04 23:31:13,588:Starting new HTTPS connection (1): free-proxy-list.net:443
urllib3.connectionpool:DEBUG:2022-10-04 23:31:14,041:https://free-proxy-list.net:443 "GET / HTTP/1.1" 200 None
urllib3.connectionpool:DEBUG:2022-10-04 23:31:14,218:Starting new HTTPS connection (1): www.newegg.com:443
urllib3.connectionpool:DEBUG:2022-10-05 22:13:30,573:Starting new HTTPS connection (1): free-proxy-list.net:443
urllib3.connectionpool:DEBUG:2022-10-05 22:13:31,364:https://free-proxy-list.net:443 "GET / HTTP/1.1" 200 None
urllib3.connectionpool:DEBUG:2022-10-05 22:13:31,611:Starting new HTTPS connection (1): www.newegg.com:443
urllib3.connectionpool:DEBUG:2022-10-05 22:13:32,782:https://www.newegg.com:443 "GET /p/pl?N=100008225%20600030002 HTTP/1.1" 200 None
urllib3.connectionpool:DEBUG:2022-10-05 22:13:52,699:Starting new HTTPS connection (1): free-proxy-list.net:443
urllib3.connectionpool:DEBUG:2022-10-05 22:13:53,246:https://free-proxy-list.net:443 "GET / HTTP/1.1" 200 None
urllib3.connectionpool:DEBUG:2022-10-05 22:13:53,508:Starting new HTTPS connection (1): www.newegg.com:443
urllib3.connectionpool:DEBUG:2022-10-05 22:13:54,319:https://www.newegg.com:443 "GET /p/pl?N=100008225%20600030002 HTTP/1.1" 200 None
urllib3.connectionpool:DEBUG:2022-10-05 22:14:12,020:Starting new HTTPS connection (1): free-proxy-list.net:443
urllib3.connectionpool:DEBUG:2022-10-05 22:14:12,510:https://free-proxy-list.net:443 "GET / HTTP/1.1" 200 None
urllib3.connectionpool:DEBUG:2022-10-05 22:14:12,771:Starting new HTTPS connection (1): www.newegg.com:443
urllib3.connectionpool:DEBUG:2022-10-05 22:14:13,151:https://www.newegg.com:443 "GET /cerwin-vega-xls-215/p/0S6-00AA-00006?quicklink=true HTTP/1.1" 200 25287
root:ERROR:2022-10-06 00:56:28,294:list indices must be integers or slices, not str
Traceback (most recent call last):
  File "C:\Users\DELL\Desktop\Python work\Products_scraper\extractors\updater.py", line 41, in update_items
    url = item['sellers']['productLink']
TypeError: list indices must be integers or slices, not str
urllib3.connectionpool:DEBUG:2022-10-06 09:25:13,600:Starting new HTTPS connection (1): www.bestbuy.com:443
urllib3.connectionpool:DEBUG:2022-10-06 09:26:00,992:Starting new HTTPS connection (1): www.bestbuy.com:443
urllib3.connectionpool:DEBUG:2022-10-06 09:26:30,335:Starting new HTTPS connection (1): www.bestbuy.com:443
urllib3.connectionpool:DEBUG:2022-10-06 09:27:36,393:Starting new HTTPS connection (1): www.bestbuy.com:443
urllib3.connectionpool:DEBUG:2022-10-06 09:27:53,051:Starting new HTTPS connection (1): www.bestbuy.com:443
urllib3.connectionpool:DEBUG:2022-10-06 09:30:09,686:Starting new HTTPS connection (1): www.bestbuy.com:443
urllib3.connectionpool:DEBUG:2022-10-06 09:30:10,813:https://www.bestbuy.com:443 "GET / HTTP/1.1" 403 264
charset_normalizer:DEBUG:2022-10-06 09:30:10,841:Encoding detection: ascii is most likely the one.
urllib3.connectionpool:DEBUG:2022-10-06 09:31:00,862:Starting new HTTPS connection (1): www.bestbuy.com:443
urllib3.connectionpool:DEBUG:2022-10-06 09:31:01,587:https://www.bestbuy.com:443 "GET /site/home-audio-systems/home-theater-systems/abcat0203000.c?id=abcat0203000 HTTP/1.1" 403 360
charset_normalizer:DEBUG:2022-10-06 09:31:01,592:Encoding detection: ascii is most likely the one.
urllib3.connectionpool:DEBUG:2022-10-06 09:31:28,672:Starting new HTTPS connection (1): www.bestbuy.com:443
urllib3.connectionpool:DEBUG:2022-10-06 09:31:29,837:https://www.bestbuy.com:443 "GET /site/home-audio-systems/home-theater-systems/abcat0203000.c?id=abcat0203000 HTTP/1.1" 403 361
charset_normalizer:DEBUG:2022-10-06 09:31:29,842:Encoding detection: ascii is most likely the one.
urllib3.connectionpool:DEBUG:2022-10-06 09:32:02,335:Starting new HTTPS connection (1): www.bestbuy.com:443
urllib3.connectionpool:DEBUG:2022-10-06 09:32:45,198:Starting new HTTPS connection (1): www.bestbuy.com:443
urllib3.connectionpool:DEBUG:2022-10-06 09:32:57,736:Starting new HTTPS connection (1): www.bestbuy.com:443
urllib3.connectionpool:DEBUG:2022-10-06 09:33:16,950:Starting new HTTPS connection (1): www.bestbuy.com:443
urllib3.connectionpool:DEBUG:2022-10-06 09:33:32,688:Starting new HTTPS connection (1): www.bestbuy.com:443
urllib3.connectionpool:DEBUG:2022-10-06 09:39:36,493:Starting new HTTPS connection (1): www.bestbuy.com:443
urllib3.connectionpool:DEBUG:2022-10-06 10:02:45,978:Starting new HTTPS connection (1): www.bestbuy.com:443
urllib3.connectionpool:DEBUG:2022-10-06 10:05:51,877:Starting new HTTPS connection (1): www.bestbuy.com:443
urllib3.connectionpool:DEBUG:2022-10-06 10:05:52,942:https://www.bestbuy.com:443 "GET /site/home-audio-systems/home-theater-systems/abcat0203000.c?id=abcat0203000 HTTP/1.1" 403 360
charset_normalizer:DEBUG:2022-10-06 10:05:52,953:Encoding detection: ascii is most likely the one.
urllib3.connectionpool:DEBUG:2022-10-06 10:09:00,005:Starting new HTTPS connection (1): www.bestbuy.com:443
urllib3.connectionpool:DEBUG:2022-10-06 10:09:01,246:https://www.bestbuy.com:443 "GET /site/home-audio-systems/home-theater-systems/abcat0203000.c?id=abcat0203000&=&render=download HTTP/1.1" 403 360
charset_normalizer:DEBUG:2022-10-06 10:09:01,251:Encoding detection: ascii is most likely the one.
urllib3.connectionpool:DEBUG:2022-10-06 10:11:19,990:Starting new HTTPS connection (1): www.bestbuy.com:443
urllib3.connectionpool:DEBUG:2022-10-06 10:12:18,213:Starting new HTTPS connection (1): www.bestbuy.com:443
urllib3.connectionpool:DEBUG:2022-10-06 10:12:52,403:Starting new HTTPS connection (1): www.bestbuy.com:443
urllib3.connectionpool:DEBUG:2022-10-06 10:14:24,947:Starting new HTTPS connection (1): www.bestbuy.com:443
urllib3.connectionpool:DEBUG:2022-10-06 10:20:40,083:Starting new HTTPS connection (1): www.bestbuy.com:443
urllib3.connectionpool:DEBUG:2022-10-06 10:20:40,544:https://www.bestbuy.com:443 "GET /site/klipsch-next-gen-reference-series-quad-3-1-2-400-watt-passive-2-way-center-channel-speaker-black/6501485.p?skuId=6501485 HTTP/1.1" 200 1657
urllib3.connectionpool:DEBUG:2022-10-06 10:21:30,536:Starting new HTTPS connection (1): www.bestbuy.com:443
urllib3.connectionpool:DEBUG:2022-10-06 10:21:30,644:https://www.bestbuy.com:443 "GET /site/home-audio-systems/home-theater-systems/abcat0203000.c?id=abcat0203000 HTTP/1.1" 200 1657
urllib3.connectionpool:DEBUG:2022-10-06 10:22:08,879:Starting new HTTPS connection (1): www.bestbuy.com:443
urllib3.connectionpool:DEBUG:2022-10-06 10:22:08,983:https://www.bestbuy.com:443 "GET /site/home-audio-systems/home-theater-systems/abcat0203000.c?id=abcat0203000 HTTP/1.1" 200 1657
urllib3.connectionpool:DEBUG:2022-10-06 10:22:31,801:Starting new HTTPS connection (1): www.bestbuy.com:443
urllib3.connectionpool:DEBUG:2022-10-06 10:22:31,947:https://www.bestbuy.com:443 "GET /site/home-audio-systems/home-theater-systems/abcat0203000.c?id=abcat0203000 HTTP/1.1" 200 1657
urllib3.connectionpool:DEBUG:2022-10-06 10:26:20,977:Starting new HTTPS connection (1): www.bestbuy.com:443
urllib3.connectionpool:DEBUG:2022-10-06 10:26:22,044:https://www.bestbuy.com:443 "GET /site/home-audio-systems/home-theater-systems/abcat0203000.c?id=abcat0203000 HTTP/1.1" 200 1657
urllib3.connectionpool:DEBUG:2022-10-06 10:27:52,354:Starting new HTTPS connection (1): www.bestbuy.com:443
urllib3.connectionpool:DEBUG:2022-10-06 10:27:52,712:https://www.bestbuy.com:443 "GET /site/home-audio-systems/home-theater-systems/abcat0203000.c?id=abcat0203000 HTTP/1.1" 200 1657
urllib3.connectionpool:DEBUG:2022-10-06 10:33:24,307:Starting new HTTPS connection (1): www.bestbuy.com:443
urllib3.connectionpool:DEBUG:2022-10-06 10:33:26,365:https://www.bestbuy.com:443 "GET /site/home-audio-systems/home-theater-systems/abcat0203000.c?id=abcat0203000 HTTP/1.1" 200 None
urllib3.connectionpool:DEBUG:2022-10-06 10:35:37,723:Starting new HTTPS connection (1): www.bestbuy.com:443
urllib3.connectionpool:DEBUG:2022-10-06 10:36:36,800:Starting new HTTPS connection (1): www.bestbuy.com:443
urllib3.connectionpool:DEBUG:2022-10-06 10:36:38,500:https://www.bestbuy.com:443 "GET /site/home-audio-systems/home-theater-systems/abcat0203000.c?id=abcat0203000 HTTP/1.1" 200 None
urllib3.connectionpool:DEBUG:2022-10-06 10:44:24,969:Starting new HTTPS connection (1): www.bestbuy.com:443
urllib3.connectionpool:DEBUG:2022-10-06 10:44:27,452:https://www.bestbuy.com:443 "GET /site/home-audio-systems/home-theater-systems/abcat0203000.c?id=abcat0203000 HTTP/1.1" 200 None
urllib3.connectionpool:DEBUG:2022-10-06 10:47:55,684:Starting new HTTPS connection (1): www.bestbuy.com:443
urllib3.connectionpool:DEBUG:2022-10-06 10:47:57,295:https://www.bestbuy.com:443 "GET /site/home-audio-systems/home-theater-systems/abcat0203000.c?id=abcat0203000 HTTP/1.1" 200 None
urllib3.connectionpool:DEBUG:2022-10-06 10:47:58,061:Starting new HTTPS connection (1): free-proxy-list.net:443
urllib3.connectionpool:DEBUG:2022-10-06 10:47:58,941:https://free-proxy-list.net:443 "GET / HTTP/1.1" 200 None
urllib3.connectionpool:DEBUG:2022-10-06 10:47:59,196:Starting new HTTPS connection (1): www.bestbuy.com:443
urllib3.connectionpool:DEBUG:2022-10-06 10:52:41,298:Starting new HTTPS connection (1): www.bestbuy.com:443
urllib3.connectionpool:DEBUG:2022-10-06 10:52:43,265:https://www.bestbuy.com:443 "GET /site/home-audio-systems/home-theater-systems/abcat0203000.c?id=abcat0203000 HTTP/1.1" 200 None
urllib3.connectionpool:DEBUG:2022-10-06 10:57:10,373:Starting new HTTPS connection (1): www.bestbuy.com:443
urllib3.connectionpool:DEBUG:2022-10-06 10:57:12,087:https://www.bestbuy.com:443 "GET /site/polk-audio-polk-reserve-series-r300-compact-center-channel-speaker-new-1-pinnacle-ring-tweeter-dual-5-25-turbine-cone-woofers-black/6465721.p?skuId=6465721 HTTP/1.1" 200 None
urllib3.connectionpool:DEBUG:2022-10-06 11:01:12,338:Starting new HTTPS connection (1): www.bestbuy.com:443
urllib3.connectionpool:DEBUG:2022-10-06 11:01:13,954:https://www.bestbuy.com:443 "GET /site/polk-audio-polk-reserve-series-r300-compact-center-channel-speaker-new-1-pinnacle-ring-tweeter-dual-5-25-turbine-cone-woofers-black/6465721.p?skuId=6465721 HTTP/1.1" 200 None
urllib3.connectionpool:DEBUG:2022-10-06 11:03:19,480:Starting new HTTPS connection (1): www.bestbuy.com:443
urllib3.connectionpool:DEBUG:2022-10-06 11:03:20,969:https://www.bestbuy.com:443 "GET /site/polk-audio-polk-reserve-series-r300-compact-center-channel-speaker-new-1-pinnacle-ring-tweeter-dual-5-25-turbine-cone-woofers-black/6465721.p?skuId=6465721 HTTP/1.1" 200 None
urllib3.connectionpool:DEBUG:2022-10-06 11:07:38,549:Starting new HTTPS connection (1): www.bestbuy.com:443
urllib3.connectionpool:DEBUG:2022-10-06 11:07:40,016:https://www.bestbuy.com:443 "GET /site/polk-audio-polk-reserve-series-r300-compact-center-channel-speaker-new-1-pinnacle-ring-tweeter-dual-5-25-turbine-cone-woofers-black/6465721.p?skuId=6465721 HTTP/1.1" 200 None
urllib3.connectionpool:DEBUG:2022-10-06 11:14:13,002:Starting new HTTPS connection (1): www.bestbuy.com:443
urllib3.connectionpool:DEBUG:2022-10-06 11:14:14,647:https://www.bestbuy.com:443 "GET /site/polk-audio-polk-reserve-series-r300-compact-center-channel-speaker-new-1-pinnacle-ring-tweeter-dual-5-25-turbine-cone-woofers-black/6465721.p?skuId=6465721 HTTP/1.1" 200 None
urllib3.connectionpool:DEBUG:2022-10-06 11:15:07,096:Starting new HTTPS connection (1): www.bestbuy.com:443
urllib3.connectionpool:DEBUG:2022-10-06 11:15:08,713:https://www.bestbuy.com:443 "GET /site/polk-audio-polk-reserve-series-r300-compact-center-channel-speaker-new-1-pinnacle-ring-tweeter-dual-5-25-turbine-cone-woofers-black/6465721.p?skuId=6465721 HTTP/1.1" 200 None
urllib3.connectionpool:DEBUG:2022-10-06 11:15:43,269:Starting new HTTPS connection (1): www.bestbuy.com:443
urllib3.connectionpool:DEBUG:2022-10-06 11:15:44,792:https://www.bestbuy.com:443 "GET /site/polk-audio-polk-reserve-series-r300-compact-center-channel-speaker-new-1-pinnacle-ring-tweeter-dual-5-25-turbine-cone-woofers-black/6465721.p?skuId=6465721 HTTP/1.1" 200 None
urllib3.connectionpool:DEBUG:2022-10-06 11:16:04,013:Starting new HTTPS connection (1): www.bestbuy.com:443
urllib3.connectionpool:DEBUG:2022-10-06 11:16:05,545:https://www.bestbuy.com:443 "GET /site/polk-audio-polk-reserve-series-r300-compact-center-channel-speaker-new-1-pinnacle-ring-tweeter-dual-5-25-turbine-cone-woofers-black/6465721.p?skuId=6465721 HTTP/1.1" 200 None
urllib3.connectionpool:DEBUG:2022-10-06 11:17:07,421:Starting new HTTPS connection (1): www.bestbuy.com:443
urllib3.connectionpool:DEBUG:2022-10-06 11:17:08,930:https://www.bestbuy.com:443 "GET /site/polk-audio-polk-reserve-series-r300-compact-center-channel-speaker-new-1-pinnacle-ring-tweeter-dual-5-25-turbine-cone-woofers-black/6465721.p?skuId=6465721 HTTP/1.1" 200 None
urllib3.connectionpool:DEBUG:2022-10-06 11:18:13,401:Starting new HTTPS connection (1): www.bestbuy.com:443
urllib3.connectionpool:DEBUG:2022-10-06 11:18:14,876:https://www.bestbuy.com:443 "GET /site/polk-audio-polk-reserve-series-r300-compact-center-channel-speaker-new-1-pinnacle-ring-tweeter-dual-5-25-turbine-cone-woofers-black/6465721.p?skuId=6465721 HTTP/1.1" 200 None
urllib3.connectionpool:DEBUG:2022-10-06 11:21:39,728:Starting new HTTPS connection (1): www.bestbuy.com:443
urllib3.connectionpool:DEBUG:2022-10-06 11:21:41,313:https://www.bestbuy.com:443 "GET /site/polk-audio-polk-reserve-series-r300-compact-center-channel-speaker-new-1-pinnacle-ring-tweeter-dual-5-25-turbine-cone-woofers-black/6465721.p?skuId=6465721 HTTP/1.1" 200 None
urllib3.connectionpool:DEBUG:2022-10-06 11:23:27,160:Starting new HTTPS connection (1): www.bestbuy.com:443
urllib3.connectionpool:DEBUG:2022-10-06 11:23:28,731:https://www.bestbuy.com:443 "GET /site/martinlogan-motion-4-90-watt-passive-2-way-center-channel-speaker-gloss-black/5870730.p?skuId=5870730 HTTP/1.1" 200 None
urllib3.connectionpool:DEBUG:2022-10-06 11:28:20,890:Starting new HTTPS connection (1): www.bestbuy.com:443
urllib3.connectionpool:DEBUG:2022-10-06 11:28:22,690:https://www.bestbuy.com:443 "GET /site/martinlogan-motion-4-90-watt-passive-2-way-center-channel-speaker-gloss-black/5870730.p?skuId=5870730 HTTP/1.1" 200 None
urllib3.connectionpool:DEBUG:2022-10-06 11:29:14,845:Starting new HTTPS connection (1): www.bestbuy.com:443
urllib3.connectionpool:DEBUG:2022-10-06 11:29:16,212:https://www.bestbuy.com:443 "GET /site/martinlogan-motion-4-90-watt-passive-2-way-center-channel-speaker-gloss-black/5870730.p?skuId=5870730 HTTP/1.1" 200 None
urllib3.connectionpool:DEBUG:2022-10-06 11:30:43,746:Starting new HTTPS connection (1): www.bestbuy.com:443
urllib3.connectionpool:DEBUG:2022-10-06 11:30:45,258:https://www.bestbuy.com:443 "GET /site/polk-audio-polk-reserve-series-r300-compact-center-channel-speaker-new-1-pinnacle-ring-tweeter-dual-5-25-turbine-cone-woofers-black/6465721.p?skuId=6465721 HTTP/1.1" 200 None
urllib3.connectionpool:DEBUG:2022-10-06 11:31:02,400:Starting new HTTPS connection (1): www.bestbuy.com:443
urllib3.connectionpool:DEBUG:2022-10-06 11:31:03,603:https://www.bestbuy.com:443 "GET /site/polk-audio-polk-reserve-series-r300-compact-center-channel-speaker-new-1-pinnacle-ring-tweeter-dual-5-25-turbine-cone-woofers-black/6465721.p?skuId=6465721 HTTP/1.1" 200 None
urllib3.connectionpool:DEBUG:2022-10-06 11:31:09,172:Starting new HTTPS connection (1): www.bestbuy.com:443
urllib3.connectionpool:DEBUG:2022-10-06 11:31:10,858:https://www.bestbuy.com:443 "GET /site/polk-audio-polk-reserve-series-r300-compact-center-channel-speaker-new-1-pinnacle-ring-tweeter-dual-5-25-turbine-cone-woofers-black/6465721.p?skuId=6465721 HTTP/1.1" 200 None
urllib3.connectionpool:DEBUG:2022-10-06 11:35:19,457:Starting new HTTPS connection (1): www.bestbuy.com:443
urllib3.connectionpool:DEBUG:2022-10-06 11:35:21,033:https://www.bestbuy.com:443 "GET /site/polk-audio-polk-reserve-series-r300-compact-center-channel-speaker-new-1-pinnacle-ring-tweeter-dual-5-25-turbine-cone-woofers-black/6465721.p?skuId=6465721 HTTP/1.1" 200 None
urllib3.connectionpool:DEBUG:2022-10-06 11:37:09,316:Starting new HTTPS connection (1): www.bestbuy.com:443
urllib3.connectionpool:DEBUG:2022-10-06 11:37:10,912:https://www.bestbuy.com:443 "GET /site/polk-audio-polk-reserve-series-r300-compact-center-channel-speaker-new-1-pinnacle-ring-tweeter-dual-5-25-turbine-cone-woofers-black/6465721.p?skuId=6465721 HTTP/1.1" 200 None
urllib3.connectionpool:DEBUG:2022-10-06 11:38:23,034:Starting new HTTPS connection (1): www.bestbuy.com:443
urllib3.connectionpool:DEBUG:2022-10-06 11:38:24,827:https://www.bestbuy.com:443 "GET /site/polk-audio-polk-reserve-series-r300-compact-center-channel-speaker-new-1-pinnacle-ring-tweeter-dual-5-25-turbine-cone-woofers-black/6465721.p?skuId=6465721 HTTP/1.1" 200 None
urllib3.connectionpool:DEBUG:2022-10-06 11:42:20,521:Starting new HTTPS connection (1): www.bestbuy.com:443
urllib3.connectionpool:DEBUG:2022-10-06 11:42:22,496:https://www.bestbuy.com:443 "GET /site/polk-audio-polk-reserve-series-r300-compact-center-channel-speaker-new-1-pinnacle-ring-tweeter-dual-5-25-turbine-cone-woofers-black/6465721.p?skuId=6465721 HTTP/1.1" 200 None
urllib3.connectionpool:DEBUG:2022-10-06 11:42:43,270:Starting new HTTPS connection (1): www.bestbuy.com:443
urllib3.connectionpool:DEBUG:2022-10-06 11:42:44,717:https://www.bestbuy.com:443 "GET /site/definitive-technology-descend-dn10-10-sub-3xr-architecture-500w-peak-class-d-amplifier-2-10-bass-radiators-black/6467273.p?skuId=6467273 HTTP/1.1" 200 None
urllib3.connectionpool:DEBUG:2022-10-06 11:43:25,695:Starting new HTTPS connection (1): www.bestbuy.com:443
urllib3.connectionpool:DEBUG:2022-10-06 11:43:27,109:https://www.bestbuy.com:443 "GET /site/definitive-technology-descend-dn10-10-sub-3xr-architecture-500w-peak-class-d-amplifier-2-10-bass-radiators-black/6467273.p?skuId=6467273 HTTP/1.1" 200 None
urllib3.connectionpool:DEBUG:2022-10-06 13:24:59,200:Starting new HTTPS connection (1): www.bestbuy.com:443
urllib3.connectionpool:DEBUG:2022-10-06 13:25:01,723:https://www.bestbuy.com:443 "GET /site/home-audio-systems/home-theater-systems/abcat0203000.c?id=abcat0203000 HTTP/1.1" 200 None
urllib3.connectionpool:DEBUG:2022-10-06 13:26:09,051:Starting new HTTPS connection (1): www.bestbuy.com:443
urllib3.connectionpool:DEBUG:2022-10-06 13:26:11,221:https://www.bestbuy.com:443 "GET /site/definitive-technology-descend-dn10-10-sub-3xr-architecture-500w-peak-class-d-amplifier-2-10-bass-radiators-black/6467273.p?skuId=6467273 HTTP/1.1" 200 None
urllib3.connectionpool:DEBUG:2022-10-06 16:03:33,289:Starting new HTTPS connection (1): www.newegg.com:443
urllib3.connectionpool:DEBUG:2022-10-06 16:03:34,902:https://www.newegg.com:443 "GET /creality-ender-3-v2-black/p/288-00DY-00001 HTTP/1.1" 200 43553
urllib3.connectionpool:DEBUG:2022-10-06 16:03:35,233:Starting new HTTPS connection (1): www.newegg.com:443
urllib3.connectionpool:DEBUG:2022-10-06 16:03:36,143:https://www.newegg.com:443 "GET /creality-ender-3-v2-black/p/288-00DY-00001 HTTP/1.1" 200 43552
urllib3.connectionpool:DEBUG:2022-10-06 16:10:46,056:Starting new HTTPS connection (1): www.newegg.com:443
urllib3.connectionpool:DEBUG:2022-10-06 16:10:47,843:https://www.newegg.com:443 "GET /creality-ender-3-v2-black/p/288-00DY-00001 HTTP/1.1" 200 43553
root:ERROR:2022-10-06 16:10:48,167:'type' object does not support item assignment
Traceback (most recent call last):
  File "C:\Users\DELL\Desktop\Python work\Products_scraper\extractors\helpers.py", line 53, in get_details_from_newegg_and_store
    results = newegg.get_all_details(url, q, category)
  File "C:\Users\DELL\Desktop\Python work\Products_scraper\extractors\newegg.py", line 147, in get_all_details
    results['productID'] = get_product_id(page)
TypeError: 'type' object does not support item assignment
urllib3.connectionpool:DEBUG:2022-10-06 16:11:46,295:Starting new HTTPS connection (1): www.newegg.com:443
urllib3.connectionpool:DEBUG:2022-10-06 16:11:48,247:https://www.newegg.com:443 "GET /creality-ender-3-v2-black/p/288-00DY-00001 HTTP/1.1" 200 44032
urllib3.connectionpool:DEBUG:2022-10-06 16:12:55,885:Starting new HTTPS connection (1): www.newegg.com:443
urllib3.connectionpool:DEBUG:2022-10-06 16:12:57,012:https://www.newegg.com:443 "GET /creality-ender-3-v2-black/p/288-00DY-00001 HTTP/1.1" 200 43525
urllib3.connectionpool:DEBUG:2022-10-06 16:27:31,713:Starting new HTTPS connection (1): www.newegg.com:443
urllib3.connectionpool:DEBUG:2022-10-06 16:27:33,291:https://www.newegg.com:443 "GET //p/0S6-00SH-00143 HTTP/1.1" 200 24112
urllib3.connectionpool:DEBUG:2022-10-06 16:27:33,553:Starting new HTTPS connection (1): www.newegg.com:443
urllib3.connectionpool:DEBUG:2022-10-06 16:27:45,754:https://www.newegg.com:443 "GET //p/0S6-00SH-00143 HTTP/1.1" 200 23806
urllib3.connectionpool:DEBUG:2022-10-06 16:28:13,376:Starting new HTTPS connection (1): www.newegg.com:443
urllib3.connectionpool:DEBUG:2022-10-06 16:28:14,525:https://www.newegg.com:443 "GET //p/0S6-00SH-00143 HTTP/1.1" 200 23806
